Workbook

Sheet 메인
A1: 항목 | B1: 값
A2: 장소 수 | B2: =COUNTA('장소'!A3:A23) -> 21
A3: 마을 수 | B3: =COUNTIF('장소'!B3:B23,"마을") -> 3
A4: 길 수 | B4: =COUNTA('길'!A2:A27) -> 26
A5: 몬스터 종류 | B5: =COUNTA('전투'!A2:A16) -> 15
A6: 고유 기믹 몬스터 | B6: =COUNTIF('전투'!Q2:Q16,"?*") -> 5
A7: 인카운터 선택지 수 | B7: =COUNTA('인카운터'!C2:C49) -> 48
A8: 장비 수 | B8: =COUNTA('장비'!A2:A15) -> 14
A9: 의뢰 수 | B9: =COUNTA('의뢰'!A2:A8) -> 7
A10: 의뢰 보상 금화 합계 | B10: =SUM('의뢰'!G2:G8) -> 152
A11: 숨겨진 보물 금화 합계 | B11: =SUM('채집_보물'!J2:J31) -> 185
A13: 이번에 바뀐 점
A14: 지도를 새 그림에 맞춰 다시 그림: 장소 18곳 + 관문 너머 출입 금지 지역 3곳(로렌시아 제국·항구·기차역), 길 색은 그림대로 초록(안전)·노랑(보통)·빨강(위험).
A15: 특별한 길: 오아시스 → 해변, 오아시스 → 사막은 일방통행(화살표). 고대 유적 ↔ 오아시스는 '숨겨진 길 찾기'(감지, 어려움 15)에 성공해야 열림. 관문 → 로렌시아 제국은 출입 금지.
A16: 채집을 6종류로 정리: 낚시(회어·금린어), 채집A(약초·독초), 채집B(산딸기·나무 열매), 버섯 따기(버섯·독버섯), 사막 채집(선인장 열매·회전초), 광석(철광석·유물 조각). 한 번에 확률대로 하나를 얻음.
A17: 마을 NPC 이름: 시작 마을(상인 케르트, 여관 알토 / 대장간 없음), 항구 마을(상인 포체, 대장장이 헤일리, 여관 캉캉), 눈 마을(상인 헬라, 대장장이 파로, 여관 이사야), 관문(경비원).
A18: 의뢰 대사와 목표를 새 지도에 맞게 수정: 4번째 의뢰는 '배에 실을 약초'(약초 4개), 7번째는 '해충 퇴치약'(독초 3개).
A19: 장비 제작 재료를 새 재료로 교체(광석 → 철광석, 물고기 → 회어 등). '상점' 시트 판매가 계산이 지력 판정 보정 칸(B31)을 보도록 바로잡음.
A21: 읽는 법
A22: 파란 글자는 게임 코드에서 가져온 값, 검은 글자는 계산식. 노란 칸(규칙, 상점의 지력 보정)을 바꾸면 관련 계산이 함께 바뀜.
A23: 이 표는 게임 파일(game.html)에서 바로 뽑아낸 값으로 만들었지만, 표를 고쳐도 게임에는 자동 반영되지 않음.
A25: 스크립트
A26: 장소(도착 묘사·채집·보물 문장), 인카운터(상황·진행·성공·실패 문장), 의뢰(의뢰·진행·완료 대사), 전투(등장·기믹·공통 전투 문장), 스크립트_공통(인사·시스템 문장) 시트에 게임 속 문장을 모두 모아 둠.

Sheet 규칙
A1: 시스템 규칙
A2: 항목 | B2: 값 | C2: 설명
A3: 주사위 | B3: 1D20 | C3: 20면체 주사위 1개. 눈 + 판정 보정 ≥ 목표 달성치면 성공
A4: 펌블 | B4: 1 | C4: 쓰는 눈(보정 전)이 1이면 무조건 실패. 주사위가 여럿이면 모두 1이어야 함
A5: 크리티컬 | B5: 20 | C5: 쓰는 눈(보정 전)이 20일 때만 무조건 성공. 보정 후 결과가 20을 넘어도 크리티컬이 아님
A6: 판정 보정 | B6: 스탯 ÷ 3 (버림) | C6: 장비로 오른 스탯 포함. 6~8 → +2, 9~11 → +3, 12~14 → +4, 15~17 → +5
A7: 캐릭터 기본 스탯 | B7: 6 | C7: 캐릭터 만들기에서 모든 스탯의 시작 값
A8: 캐릭터 만들기 점수 | B8: 16 | C8: 자유롭게 나누는 점수 (모두 써야 시작)
A9: 캐릭터 만들기 상한 | B9: 13 | C9: 만들 때 한 스탯의 최대치
A10: 훈련 상한 | B10: 15 | C10: 훈련장에서 올릴 수 있는 기본 스탯 최대치 (장비 제외)
A11: 훈련 비용 배수 | B11: 2 | C11: 다음 1점 비용 = 지금 기본 스탯 × 이 값 (금화)
A12: 체력 최대 | B12: 20 | C12: 전투 패배, 함정으로 깎이고 마을에서 회복. 0이면 가장 가까운 마을에서 체력 5로 깨어남
A13: 시작 금화 | B13: 5
A14: 전투 HP | B14: 10 | C14: 전투마다 새로 시작하는 HP (체력과 별개)
A15: 전투 라운드 간격(초) | B15: 1.5 | C15: 라운드를 쓰는 행동: 공격, 대응(기믹이 있을 때). 방어는 적이 공격할 때마다 반응
A16: 사건 중 전투 비율 | B16: 0.6 | C16: 이동 중 사건이 일어났을 때 전투일 확률
A17: 이동 시간 배율 | B17: 1 | C17: 1이면 이동 1/3/5초
A18: 도전 시간 배율 | B18: 1 | C18: 1이면 도전 1~5초
A19: 쿨타임 감시 시간(초) | B19: 60 | C19: 이 시간 안에
A20: 쿨타임 횟수 | B20: 3 | C20: 같은 장소 도전을 이만큼 하면
A21: 쿨타임(초) | B21: 10 | C21: 이만큼 다시 할 수 없음 (걸렸을 때만 표시)
A22: 타자 효과 간격(ms) | B22: 28 | C22: 대사·장소 묘사가 한 글자씩 나오는 간격. 이야기 칸을 클릭하면 바로 전부 나옴
A25: 단계 | B25: 이름 | C25: 목표 달성치 | D25: 시간 단계(초) | E25: 도전 시간(초)
A26: 1 | B26: 매우 쉬움 | C26: 6 | D26: 1 | E26: =D26*'규칙'!$B$18 -> 1
A27: 2 | B27: 쉬움 | C27: 9 | D27: 2 | E27: =D27*'규칙'!$B$18 -> 2
A28: 3 | B28: 보통 | C28: 12 | D28: 3 | E28: =D28*'규칙'!$B$18 -> 3
A29: 4 | B29: 어려움 | C29: 15 | D29: 4 | E29: =D29*'규칙'!$B$18 -> 4
A30: 5 | B30: 매우 어려움 | C30: 18 | D30: 5 | E30: =D30*'규칙'!$B$18 -> 5
A32: 목표 달성치와 시간은 공격, 방어, 대응, 도망, 도전에 공통으로 쓰임. 이동은 시간 단계 1/3/5만 씀.
A33: 성공 확률 = 1D20에서 (눈 + 보정) ≥ 목표일 확률. 눈 1(5%)은 실패, 눈 20(5%)은 성공. 매직 주사위·행운의 추가 굴림은 제외.
A36: 코드 | B36: 위험도 | C36: 시간 단계 | D36: 이동 시간(초) | E36: 사건 확률 | F36: 전투 확률
A37: low | B37: 안전 | C37: 5 | D37: =E30 -> 5 | E37: 0.25 | F37: =E37*'규칙'!$B$16 -> 0.15
A38: mid | B38: 보통 | C38: 3 | D38: =E28 -> 3 | E38: 0.4 | F38: =E38*'규칙'!$B$16 -> 0.24
A39: high | B39: 위험 | C39: 1 | D39: =E26 -> 1 | E39: 0.72 | F39: =E39*'규칙'!$B$16 -> 0.432
A41: 위험한 길은 지름길이라 빠르지만 사건이 잦음. 감지 판정 보정이 +2보다 1 높을 때마다 사건 확률 -2%p (최소 5%).
A43: 스탯
A44: 스탯 | B44: 효과
A45: 근력 | B45: 근거리 무기(맨손 포함) 공격, 광석 캐기, 버티기
A46: 정신 | B46: 방어 판정, 사역마 공격, 무시하기·그냥 두기 같은 선택
A47: 민첩 | B47: 원거리 무기 공격, 도망 판정, 몸을 쓰는 회피
...

Sheet 스크립트_공통
A1: 상황 | B1: 때 | C1: 문장 | D1: 표시 방식
A2: 시작 | B2: 캐릭터 만들기 안내 | C2: 당신이 어떤 축복을 안고 태어났는지 고하라. 총 16점을 자유롭게 분배한다. 메이킹 시점 스탯의 하한은 6, 상한은 13이다. | D2: 즉시
A3: 시작 | B3: 게임 시작 | C3: 제국의 수도 인근에 있는 작은 마을. 수도와 인접한 덕에 재앙이 일어나기 시작한 당시 발빠르게 축복을 받았고, 덕분에 강한 몬스터가 상대적으로 적다고 한다. 그만큼 축복의 영향력을 벗어난 구역에는 손쓸 수 없이 강한 것들도 있는 모양이지만. 어쨌든, 모험을 시작하기에 알맞은 곳이다. 당신의 부모, 보호자, 혹은 지난 동료나 선배 모험가는 이렇게 말했을 것이다─그 마을에 도착하면, 여관에 먼저 가 보라고. | D3: 타자
A4: 시작 마을 | B4: 상점 기본 | C4: 마을의 유일한 상점. 이름을 표시하는 팻말에는 유려한 글씨로 이렇게 적혀 있다: 넛츠 프레젠트. 가게 내부를 몇 번 증축한 듯 벽의 한쪽이 판자로 기워져 있고, 각종 초보 모험가에게 알맞을 법한 것들이 진열되어 있다. | D4: 타자
A5: 시작 마을 | B5: 상점 - 상인 인사 | C5: 사냥개 한 마리가 당신에게 호기심을 품고 고개를 숙여 냄새를 맡는다. 개가 코를 들고 당신에게 다가서려 하면, 흰 손이 그것을 막는다. 긴 귀에 머리카락을 걸친 느슨한 인상의 주인이 미소를 띠고 가볍게 인사한다. 상인, 케르트 | 어서 와. 뭐 좀 살래? | D5: 타자
A6: 시작 마을 | B6: 상점 - 상인 이야기 | C6: 상인, 케르트 | 이곳은 늘 모험을 시작하려는 젊은 모험가들로 북적이지. 상인, 케르트 | 덕분에 수도에 기생하는 꼴이었던 옛날의 모습을 완전히 벗어던지고, 이렇게나 많은 사람으로 붐비고 있어. 케르트의 시선이 문의 바깥으로 향한다. 낯선 사람들이 바쁘게 걸어다니고, 갓 만든 음식 냄새가 부드럽게 풍겨 온다. 상인, 케르트 | 가끔은 용이 불러온 재앙이 기쁜 일인지, 슬픈 일인지 잘 모르겠다는 생각도 들어. ...후후, 실언이었을까. | D6: 타자
A7: 시작 마을 | B7: 상점 - 상인 이야기 후 인사 | C7: 상인, 케르트 | 물건은 얼마든지 구경해도 좋아. 늘 네게 부담 없는 거래처가 되길 바라. | D7: 타자
A8: 시작 마을 | B8: 여관 기본 | C8: 높은 음 여관. 수도 반대편에 있는 두 길의 사이에 이리로 오라는 듯 자리잡고 있다. 여관 입구의 흙길로 얼마나 많은 사람이 오갔는지, 더없이 단단해 먼지조차 일지 않는다. 낡은 마룻바닥에 여러 명의 발소리가 울리고, 그 안쪽으로부터는 갓 만든 음식의 냄새가 흘러나온다. | D8: 타자
A9: 시작 마을 | B9: 여관 - 여관주인 인사 | C9: 여관의 안쪽으로 들어서면, 주인이 바쁘게 장부를 쓰다가 당신을 보고 고개를 든다. 여관 주인, 알토 | 어머, 정신 좀 봐! 어서오세요, 높은 음 여관이랍니다! | D9: 타자
A10: 시작 마을 | B10: 여관 - 여관주인 이야기 | C10: 여관 주인, 알토 | 지난 여름에, 마을이 곰의 습격을 받았단다. 이 주변에서는 잘 발견되지 않는 아주 흉포하고 무서운 녀석이었지! 여관 주인, 알토 | 평범한 마을이었다면 무너지고 말았을 텐데, 다행히 마을에 온 초보 모험가들이 열심히 힘을 써 주었어. 많이들 다치고 죽었지만 마을만은 무사했단다. 문득 무언가 발코에 닿는다. 더러워진 성표가 주인을 잃고 발에 차여 여관 바닥을 구르고 있다. 여관 주인, 알토 | 축복은 이미 끝났어. 새로운 모험가가 이 마을을 구하고 있을 뿐이지. | D10: 타자
A11: 시작 마을 | B11: 여관 - 여관 휴식 | C11: 여관 주인, 알토 | ...괜찮니? 안색이 많이 나쁜 것 같은데. 여관 주인, 알토 | 여기, 위층에 있는 방의 열쇠란다. 몸이 나아질 때까지는 무리하지 말고 쉬도록 하렴. 숙박비는 후불로 내도 괜찮으니까, 알았지? 알토가 당신의 손에 나무로 만들어진 표식이 달린 열쇠를 하나 쥐여 준다. 생각보다 묵직하다. | D11: 타자
A12: 시작 마을 | B12: 여관 - 여관 휴식 후 | C12: 시간을 들여 다친 곳을 치료하고 휴식을 취했다. 여관 키를 반납하고, 여관 앞 수없이 밟혀 단단해진 흙 위로 걸음을 내딛는다. | D12: 타자
... A56: 체력 | B56: 체력 0 | C56: 체력이 바닥나 의식을 잃었다... 가장 가까운 마을({마을})에서 눈을 떴다. (체력 5로 회복) | D56: 즉시
A58: { } 안은 게임 중 실제 값으로 바뀌는 자리. '타자'는 한 글자씩 나오며 이야기 칸을 클릭하면 바로 전부 나옴.

Sheet 길
A1: 장소 A | B1: 장소 B | C1: 코드 | D1: 위험도 | E1: 이동 시간(초) | F1: 사건 확률 | G1: 전투 확률 | H1: 비고
A2: 협곡 | B2: 설원 | C2: high | D2: {=INDEX('규칙'!$B$37:$B$39,MATCH(C2,'규칙'!$A$37:$A$39,0))} -> 위험 | E2: {=INDEX('규칙'!$D$37:$D$39,MATCH(C2,'규칙'!$A$37:$A$39,0))} -> 1 | F2: {=INDEX('규칙'!$E$37:$E$39,MATCH(C2,'규칙'!$A$37:$A$39,0))} -> 0.72 | G2: {=INDEX('규칙'!$F$37:$F$39,MATCH(C2,'규칙'!$A$37:$A$39,0))} -> 0.432
A3: 협곡 | B3: 산(서) | C3: mid | D3: {=INDEX('규칙'!$B$37:$B$39,MATCH(C3,'규칙'!$A$37:$A$39,0))} -> 보통 | E3: {=INDEX('규칙'!$D$37:$D$39,MATCH(C3,'규칙'!$A$37:$A$39,0))} -> 3 | F3: {=INDEX('규칙'!$E$37:$E$39,MATCH(C3,'규칙'!$A$37:$A$39,0))} -> 0.4 | G3: {=INDEX('규칙'!$F$37:$F$39,MATCH(C3,'규칙'!$A$37:$A$39,0))} -> 0.24
A4: 설원 | B4: 눈 마을 | C4: mid | D4: {=INDEX('규칙'!$B$37:$B$39,MATCH(C4,'규칙'!$A$37:$A$39,0))} -> 보통 | E4: {=INDEX('규칙'!$D$37:$D$39,MATCH(C4,'규칙'!$A$37:$A$39,0))} -> 3 | F4: {=INDEX('규칙'!$E$37:$E$39,MATCH(C4,'규칙'!$A$37:$A$39,0))} -> 0.4 | G4: {=INDEX('규칙'!$F$37:$F$39,MATCH(C4,'규칙'!$A$37:$A$39,0))} -> 0.24
A5: 눈 마을 | B5: 산(동) | C5: mid | D5: {=INDEX('규칙'!$B$37:$B$39,MATCH(C5,'규칙'!$A$37:$A$39,0))} -> 보통 | E5: {=INDEX('규칙'!$D$37:$D$39,MATCH(C5,'규칙'!$A$37:$A$39,0))} -> 3 | F5: {=INDEX('규칙'!$E$37:$E$39,MATCH(C5,'규칙'!$A$37:$A$39,0))} -> 0.4 | G5: {=INDEX('규칙'!$F$37:$F$39,MATCH(C5,'규칙'!$A$37:$A$39,0))} -> 0.24
A6: 동굴(북) | B6: 산(동) | C6: high | D6: {=INDEX('규칙'!$B$37:$B$39,MATCH(C6,'규칙'!$A$37:$A$39,0))} -> 위험 | E6: {=INDEX('규칙'!$D$37:$D$39,MATCH(C6,'규칙'!$A$37:$A$39,0))} -> 1 | F6: {=INDEX('규칙'!$E$37:$E$39,MATCH(C6,'규칙'!$A$37:$A$39,0))} -> 0.72 | G6: {=INDEX('규칙'!$F$37:$F$39,MATCH(C6,'규칙'!$A$37:$A$39,0))} -> 0.432
A7: 산(동) | B7: 숲 | C7: mid | D7: {=INDEX('규칙'!$B$37:$B$39,MATCH(C7,'규칙'!$A$37:$A$39,0))} -> 보통 | E7: {=INDEX('규칙'!$D$37:$D$39,MATCH(C7,'규칙'!$A$37:$A$39,0))} -> 3 | F7: {=INDEX('규칙'!$E$37:$E$39,MATCH(C7,'규칙'!$A$37:$A$39,0))} -> 0.4 | G7: {=INDEX('규칙'!$F$37:$F$39,MATCH(C7,'규칙'!$A$37:$A$39,0))} -> 0.24
A8: 호수 | B8: 산(서) | C8: low | D8: {=INDEX('규칙'!$B$37:$B$39,MATCH(C8,'규칙'!$A$37:$A$39,0))} -> 안전 | E8: {=INDEX('규칙'!$D$37:$D$39,MATCH(C8,'규칙'!$A$37:$A$39,0))} -> 5 | F8: {=INDEX('규칙'!$E$37:$E$39,MATCH(C8,'규칙'!$A$37:$A$39,0))} -> 0.25 | G8: {=INDEX('규칙'!$F$37:$F$39,MATCH(C8,'규칙'!$A$37:$A$39,0))} -> 0.15
A9: 호수 | B9: 항구 마을 | C9: low | D9: {=INDEX('규칙'!$B$37:$B$39,MATCH(C9,'규칙'!$A$37:$A$39,0))} -> 안전 | E9: {=INDEX('규칙'!$D$37:$D$39,MATCH(C9,'규칙'!$A$37:$A$39,0))} -> 5 | F9: {=INDEX('규칙'!$E$37:$E$39,MATCH(C9,'규칙'!$A$37:$A$39,0))} -> 0.25 | G9: {=INDEX('규칙'!$F$37:$F$39,MATCH(C9,'규칙'!$A$37:$A$39,0))} -> 0.15
A10: 산(서) | B10: 늪지 | C10: high | D10: {=INDEX('규칙'!$B$37:$B$39,MATCH(C10,'규칙'!$A$37:$A$39,0))} -> 위험 | E10: {=INDEX('규칙'!$D$37:$D$39,MATCH(C10,'규칙'!$A$37:$A$39,0))} -> 1 | F10: {=INDEX('규칙'!$E$37:$E$39,MATCH(C10,'규칙'!$A$37:$A$39,0))} -> 0.72 | G10: {=INDEX('규칙'!$F$37:$F$39,MATCH(C10,'규칙'!$A$37:$A$39,0))} -> 0.432
A11: 산(서) | B11: 초원 | C11: low | D11: {=INDEX('규칙'!$B$37:$B$39,MATCH(C11,'규칙'!$A$37:$A$39,0))} -> 안전 | E11: {=INDEX('규칙'!$D$37:$D$39,MATCH(C11,'규칙'!$A$37:$A$39,0))} -> 5 | F11: {=INDEX('규칙'!$E$37:$E$39,MATCH(C11,'규칙'!$A$37:$A$39,0))} -> 0.25 | G11: {=INDEX('규칙'!$F$37:$F$39,MATCH(C11,'규칙'!$A$37:$A$39,0))} -> 0.15
A12: 항구 마을 | B12: 늪지 | C12: high | D12: {=INDEX('규칙'!$B$37:$B$39,MATCH(C12,'규칙'!$A$37:$A$39,0))} -> 위험 | E12: {=INDEX('규칙'!$D$37:$D$39,MATCH(C12,'규칙'!$A$37:$A$39,0))} -> 1 | F12: {=INDEX('규칙'!$E$37:$E$39,MATCH(C12,'규칙'!$A$37:$A$39,0))} -> 0.72 | G12: {=INDEX('규칙'!$F$37:$F$39,MATCH(C12,'규칙'!$A$37:$A$39,0))} -> 0.432
A13: 항구 마을 | B13: 해변 | C13: low | D13: {=INDEX('규칙'!$B$37:$B$39,MATCH(C13,'규칙'!$A$37:$A$39,0))} -> 안전 | E13: {=INDEX('규칙'!$D$37:$D$39,MATCH(C13,'규칙'!$A$37:$A$39,0))} -> 5 | F13: {=INDEX('규칙'!$E$37:$E$39,MATCH(C13,'규칙'!$A$37:$A$39,0))} -> 0.25 | G13: {=INDEX('규칙'!$F$37:$F$39,MATCH(C13,'규칙'!$A$37:$A$39,0))} -> 0.15
... A21: 시작 마을 | B21: 관문 | C21: mid | D21: {=INDEX('규칙'!$B$37:$B$39,MATCH(C21,'규칙'!$A$37:$A$39,0))} -> 보통 | E21: {=INDEX('규칙'!$D$37:$D$39,MATCH(C21,'규칙'!$A$37:$A$39,0))} -> 3 | F21: {=INDEX('규칙'!$E$37:$E$39,MATCH(C21,'규칙'!$A$37:$A$39,0))} -> 0.4 | G21: {=INDEX('규칙'!$F$37:$F$39,MATCH(C21,'규칙'!$A$37:$A$39,0))} -> 0.24
A22: 오아시스 | B22: 해변 | C22: low | D22: {=INDEX('규칙'!$B$37:$B$39,MATCH(C22,'규칙'!$A$37:$A$39,0))} -> 안전 | E22: {=INDEX('규칙'!$D$37:$D$39,MATCH(C22,'규칙'!$A$37:$A$39,0))} -> 5 | F22: {=INDEX('규칙'!$E$37:$E$39,MATCH(C22,'규칙'!$A$37:$A$39,0))} -> 0.25 | G22: {=INDEX('규칙'!$F$37:$F$39,MATCH(C22,'규칙'!$A$37:$A$39,0))} -> 0.15 | H22: 일방통행: 오아시스 → 해변만 가능
A23: 오아시스 | B23: 사막 | C23: low | D23: {=INDEX('규칙'!$B$37:$B$39,MATCH(C23,'규칙'!$A$37:$A$39,0))} -> 안전 | E23: {=INDEX('규칙'!$D$37:$D$39,MATCH(C23,'규칙'!$A$37:$A$39,0))} -> 5 | F23: {=INDEX('규칙'!$E$37:$E$39,MATCH(C23,'규칙'!$A$37:$A$39,0))} -> 0.25 | G23: {=INDEX('규칙'!$F$37:$F$39,MATCH(C23,'규칙'!$A$37:$A$39,0))} -> 0.15 | H23: 일방통행: 오아시스 → 사막만 가능
A24: 고대 유적 | B24: 오아시스 | C24: high | D24: {=INDEX('규칙'!$B$37:$B$39,MATCH(C24,'규칙'!$A$37:$A$39,0))} -> 위험 | E24: {=INDEX('규칙'!$D$37:$D$39,MATCH(C24,'규칙'!$A$37:$A$39,0))} -> 1 | F24: {=INDEX('규칙'!$E$37:$E$39,MATCH(C24,'규칙'!$A$37:$A$39,0))} -> 0.72 | G24: {=INDEX('규칙'!$F$37:$F$39,MATCH(C24,'규칙'!$A$37:$A$39,0))} -> 0.432 | H24: 숨겨진 길: 고대 유적에서 '숨겨진 길 찾기'에 성공하면 열림
A25: 관문 | B25: 로렌시아 제국 | C25: low | D25: {=INDEX('규칙'!$B$37:$B$39,MATCH(C25,'규칙'!$A$37:$A$39,0))} -> 안전 | E25: {=INDEX('규칙'!$D$37:$D$39,MATCH(C25,'규칙'!$A$37:$A$39,0))} -> 5 | F25: {=INDEX('규칙'!$E$37:$E$39,MATCH(C25,'규칙'!$A$37:$A$39,0))} -> 0.25 | G25: {=INDEX('규칙'!$F$37:$F$39,MATCH(C25,'규칙'!$A$37:$A$39,0))} -> 0.15 | H25: 출입 금지 (관문 경비원이 막음)
A26: 로렌시아 제국 | B26: 항구 | C26: low | D26: {=INDEX('규칙'!$B$37:$B$39,MATCH(C26,'규칙'!$A$37:$A$39,0))} -> 안전 | E26: {=INDEX('규칙'!$D$37:$D$39,MATCH(C26,'규칙'!$A$37:$A$39,0))} -> 5 | F26: {=INDEX('규칙'!$E$37:$E$39,MATCH(C26,'규칙'!$A$37:$A$39,0))} -> 0.25 | G26: {=INDEX('규칙'!$F$37:$F$39,MATCH(C26,'규칙'!$A$37:$A$39,0))} -> 0.15 | H26: 관문 너머 지역 (현재 갈 수 없음)
A27: 로렌시아 제국 | B27: 기차역 | C27: low | D27: {=INDEX('규칙'!$B$37:$B$39,MATCH(C27,'규칙'!$A$37:$A$39,0))} -> 안전 | E27: {=INDEX('규칙'!$D$37:$D$39,MATCH(C27,'규칙'!$A$37:$A$39,0))} -> 5 | F27: {=INDEX('규칙'!$E$37:$E$39,MATCH(C27,'규칙'!$A$37:$A$39,0))} -> 0.25 | G27: {=INDEX('규칙'!$F$37:$F$39,MATCH(C27,'규칙'!$A$37:$A$39,0))} -> 0.15 | H27: 관문 너머 지역 (현재 갈 수 없음)

Sheet 장소
A1: 장소
A2: 장소 | B2: 구분 | C2: 이어진 장소 | D2: 출현 몬스터 | E2: 시설 | F2: 도착했을 때 묘사 (타자 효과) | G2: 채집 행동 (진행 문구) | H2: 숨겨진 보물 발견 문장
A3: 시작 마을 | B3: 마을 | C3: 숲, 초원, 관문 | D3: 슬라임 | E3: 상점(케르트), 여관(알토) | F3: 제국의 수도 인근에 있는 작은 마을. 수도와 인접한 덕에 재앙이 일어나기 시작한 당시 발빠르게 축복을 받았고, 덕분에 강한 몬스터가 상대적으로 적다고 한다. 그만큼 축복의 영향력을 벗어난 구역에는 손쓸 수 없이 강한 것들도 있는 모양이지만. | H3: 마을 구석 살펴보기: 낡은 장독대 밑에서 숨겨진 보물상자를 찾았다! 금화 15닢을 얻었다!
A4: 숲 | B4: 야생 | C4: 산(동), 시작 마을, 관문 | D4: 슬라임, 고블린, 멧돼지 | E4: - | F4: [숲] 키 큰 나무가 햇빛을 가린다. 어디선가 새소리가 들린다. | G4: 열매 따기(산딸기·나무 열매) - 열매 따는 중... / 버섯 따기(버섯·독버섯) - 버섯 따는 중...
A5: 초원 | B5: 야생 | C5: 산(서), 늪지, 시작 마을, 사막 | D5: 멧돼지, 늑대 | E5: - | F5: [초원] 바람에 풀이 물결치는 넓은 초원이다. 멀리서 짐승 울음소리가 들린다. | G5: 버섯 따기(버섯·독버섯) - 버섯 따는 중... / 열매 따기(산딸기·나무 열매) - 열매 따는 중...
A6: 호수 | B6: 야생 | C6: 산(서), 항구 마을 | D6: 슬라임 | E6: - | F6: [호수] 잔잔한 호수에 구름이 비친다. 물가에 작은 배가 묶여 있다. | G6: 낚시하기(회어·금린어) - 호숫가에서 낚시 중...
A7: 산(서) | B7: 야생 | C7: 협곡, 호수, 늪지, 초원 | D7: 늑대, 곰 | E7: - | F7: [산] 서쪽 산의 정상에 오르니 호수와 초원이 한눈에 내려다보인다. | G7: 약초 채집(약초·독초) - 약초 채집 중... / 버섯 따기(버섯·독버섯) - 버섯 따는 중... | H7: 정상 근처 살펴보기: 바위 아래에서 오래된 보물상자를 발견했다! 금화 12닢을 얻었다!
A8: 산(동) | B8: 야생 | C8: 눈 마을, 동굴(북), 숲 | D8: 늑대, 곰 | E8: - | F8: [산] 바람이 거센 동쪽 산등성이다. 멀리 눈 덮인 봉우리가 보인다. | G8: 약초 채집(약초·독초) - 약초 채집 중...
A9: 늪지 | B9: 야생 | C9: 산(서), 항구 마을, 초원 | D9: 독사, 악어 | E9: - | F9: [늪지] 발이 푹푹 빠지는 축축한 늪이다. 안개 사이로 무언가 움직인다. | G9: 약초 채집(약초·독초) - 약초 채집 중... | H9: 늪 속 살펴보기: 진흙 속에 가라앉은 보물상자를 건져 올렸다! 금화 18닢을 얻었다!
A10: 항구 마을 | B10: 마을 | C10: 호수, 늪지, 해변 | D10: 게 | E10: 상점(포체), 대장간·훈련장(헤일리), 여관(캉캉) | F10: [항구 마을] 갈매기가 날고 짠 바람이 부는 항구 마을이다. 배와 상인으로 북적인다. | H10: 부두 창고 살펴보기: 낡은 창고 구석에서 숨겨진 보물상자를 찾았다! 금화 18닢을 얻었다!
A11: 해변 | B11: 야생 | C11: 항구 마을, 오아시스(일방통행으로 들어옴) | D11: 게, 갈매기 떼 | E11: - | F11: [해변] 하얀 모래와 파도 소리가 이어지는 해변이다. | G11: 낚시하기(회어·금린어) - 바닷가에서 낚시 중...
A12: 협곡 | B12: 야생 | C12: 설원, 산(서) | D12: 전갈, 곰 | E12: - | F12: [협곡] 붉은 절벽 사이로 바람이 휘몰아치는 깊은 협곡이다. | G12: 열매 따기(산딸기·나무 열매) - 열매 따는 중... / 광석 캐기(철광석·유물 조각) - 광석 캐는 중... | H12: 절벽 틈 살펴보기: 절벽 틈에서 숨겨진 보물상자를 발견했다! 금화 22닢을 얻었다!
A13: 설원 | B13: 야생 | C13: 협곡, 눈 마을 | D13: 설원 늑대, 곰 | E13: - | F13: [설원] 눈이 무릎까지 쌓인 하얀 벌판이다. 숨결이 하얗게 흩어진다. | G13: 약초 채집(약초·독초) - 눈을 헤치며 약초 채집 중...
A14: 눈 마을 | B14: 마을 | C14: 설원, 산(동) | D14: 설원 늑대 | E14: 상점(헬라), 대장간·훈련장(파로), 여관(이사야) | F14: 제국의 수도 북쪽에 위치한 설산의 초입에 자리한 작은 마을. 마을 곳곳이 눈 속에 묻혀, 다음에도 이곳에 온다면 길을 찾을 수 있을지 의문이 든다. 어쩌면 파묻힌 채로 숨어 있기 때문에 이런 곳에 남을 수 있었던 것일지도. | H14: 눈 덮인 헛간 살펴보기: 건초 더미 아래에서 숨겨진 보물상자를 발견했다! 금화 25닢을 얻었다!
A15: 동굴(북) | B15: 야생 | C15: 산(동) | D15: 동굴 박쥐, 고블린 | E15: - | F15: [동굴] 차가운 바람이 흘러나오는 어두운 동굴이다. 안쪽에서 물 떨어지는 소리가 들린다. | G15: 광석 캐기(철광석·유물 조각) - 광석 캐는 중... / 낚시하기(회어·금린어) - 지하 물웅덩이에서 낚시 중... | H15: 동굴 안쪽 살펴보기: 바위 틈 안쪽에서 숨겨진 보물상자를 발견했다! 금화 20닢을 얻었다!
A16: 동굴(남) | B16: 야생 | C16: 고대 유적, 사막 | D16: 동굴 박쥐, 전갈 | E16: - | F16: [동굴] 모래가 흘러든 메마른 동굴이다. 벽면 곳곳이 반짝인다. | G16: 광석 캐기(철광석·유물 조각) - 광석 캐는 중...
A17: 고대 유적 | B17: 야생 | C17: 동굴(남), 오아시스(숨겨진 길) | D17: 해골 병사, 골렘 | E17: - | F17: [고대 유적] 이끼 낀 돌기둥이 늘어선 옛 유적이다. 알 수 없는 문양이 새겨져 있다. | G17: 광석 캐기(철광석·유물 조각) - 유물 조각을 발굴 중... / 숨겨진 길 찾기 - 숨겨진 길을 찾는 중... | H17: 제단 뒤 살펴보기: 무너진 제단 뒤에서 고대의 보물상자를 발견했다! 금화 30닢을 얻었다! 숨겨진 길 찾기: 무너진 벽 너머로 모래에 덮인 좁은 길을 찾아냈다! 남서쪽 오아시스로 이어지는 듯하다.
A18: 사막 | B18: 야생 | C18: 초원, 동굴(남), 오아시스(일방통행으로 들어옴) | D18: 전갈, 모래 도마뱀 | E18: - | F18: [사막] 끝없는 모래 언덕이 이어진다. 뜨거운 열기가 올라온다. | G18: 사막 채집(선인장 열매·회전초) - 사막 채집 중...
A19: 오아시스 | B19: 야생 | C19: 해변(일방통행→), 사막(일방통행→), 고대 유적(숨겨진 길) | D19: 악어, 모래 도마뱀 | E19: - | F19: [오아시스] 야자나무가 둘러싼 푸른 물웅덩이다. 지친 몸이 절로 풀린다. | G19: 낚시하기(회어·금린어) - 물가에서 낚시 중... / 사막 채집(선인장 열매·회전초) - 사막 채집 중... | H19: 물가 살펴보기: 물속에서 반짝이는 보물상자를 건져 올렸다! 금화 25닢을 얻었다!
A20: 관문 | B20: 관문 | C20: 숲, 시작 마을, 로렌시아 제국(출입 금지) | D20: 고블린 | E20: 경비원 | F20: [관문] 제국으로 이어지는 돌 관문이다. 무장한 경비원이 길을 막고 서 있다.
A21: 로렌시아 제국 | B21: 출입 금지 | C21: 관문(출입 금지), 항구(갈 수 없음), 기차역(갈 수 없음) | D21: - | E21: - | F21: (출입 금지 지역 - 지도에 흐리게 표시)
A22: 항구 | B22: 출입 금지 | C22: 로렌시아 제국(갈 수 없음) | D22: - | E22: - | F22: (출입 금지 지역 - 지도에 흐리게 표시)
A23: 기차역 | B23: 출입 금지 | C23: 로렌시아 제국(갈 수 없음) | D23: - | E23: - | F23: (출입 금지 지역 - 지도에 흐리게 표시)
A25: 산(서)·산(동), 동굴(북)·동굴(남)은 게임에서는 모두 '산', '동굴'로 표시되며 이 표에서만 구분함. 로렌시아 제국·항구·기차역은 관문 너머 지역으로 현재 출입 금지.

Sheet 인카운터
A1: 사건 | B1: 일어나는 곳 | C1: 상황 묘사 (타자 효과) | D1: 선택지 | E1: 판정 스탯 | F1: 단계 | G1: 목표 | H1: 시간(초) | I1: 진행 문구 | J1: 성공 문장 | K1: 실패 문장 | L1: 성공 보상
A2: 길 잃은 모험가 | B2: 어디서나 | C2: [길 잃은 모험가] 지도를 거꾸로 든 모험가가 두리번거리고 있다. | D2: 길을 알려 준다 | E2: 지력 | F2: 2 | G2: 9 | H2: 2 | I2: [길 잃은 모험가] 길을 알려 주는 중... | J2: 모험가가 고마워하며 동전 몇 닢을 건넸다. 모험가가 감동해 섬의 비밀 이야기를 들려주었다. | K2: 길을 잘못 알려 줘서 모험가가 반대쪽으로 사라졌다... | L2: 금화 +2
A3: 길 잃은 모험가 | B3: 어디서나 | C3: [길 잃은 모험가] 지도를 거꾸로 든 모험가가 두리번거리고 있다. | D3: 지도를 함께 살펴본다 | E3: 감지 | F3: 2 | G3: 9 | H3: 2 | I3: [길 잃은 모험가] 지도를 함께 살피는 중... | J3: 지도에 표시되지 않은 지름길을 함께 찾아냈다! 모험가가 사례를 했다. | K3: 둘 다 지도를 읽지 못해 한참 헤맸다. | L3: 금화 +3
A4: 길 잃은 모험가 | B4: 어디서나 | C4: [길 잃은 모험가] 지도를 거꾸로 든 모험가가 두리번거리고 있다. | D4: 모른 척 지나간다 | E4: 민첩 | F4: 1 | G4: 6 | H4: 1 | I4: [길 잃은 모험가] 슬그머니 지나가는 중... | J4: 들키지 않고 조용히 지나쳤다. | K4: 모험가가 '저기요!' 하며 한참을 따라왔다.
A5: 수상한 상인 | B5: 어디서나 | C5: [수상한 상인] 나무 뒤에서 커다란 배낭을 멘 상인이 손짓한다. | D5: 물건을 구경한다 | E5: 지력 | F5: 2 | G5: 9 | H5: 2 | I5: [수상한 상인] 물건을 구경하는 중... | J5: 싸고 좋은 약초를 하나 골라냈다. | K5: 바가지를 쓸 뻔해서 도망치듯 나왔다. | L5: 약초 +1
A6: 수상한 상인 | B6: 어디서나 | C6: [수상한 상인] 나무 뒤에서 커다란 배낭을 멘 상인이 손짓한다. | D6: 흥정을 한다 | E6: 행운 | F6: 3 | G6: 12 | H6: 3 | I6: [수상한 상인] 흥정하는 중... | J6: 상인이 실수로 거스름돈을 더 줬다! | K6: 상인의 말솜씨에 넘어가 아무것도 얻지 못했다. | L6: 금화 +5
A7: 수상한 상인 | B7: 어디서나 | C7: [수상한 상인] 나무 뒤에서 커다란 배낭을 멘 상인이 손짓한다. | D7: 무시한다 | E7: 정신 | F7: 1 | G7: 6 | H7: 1 | I7: [수상한 상인] 외면하는 중... | J7: 상인이 아쉬운 듯 배낭을 다시 여몄다. | K7: 상인이 끈질기게 따라오며 물건을 들이밀었다.
A8: 반짝이는 상자 | B8: 어디서나 | C8: [반짝이는 상자] 길가에 낡은 보물상자가 놓여 있다. | D8: 열어 본다 | E8: 재주 | F8: 3 | G8: 12 | H8: 3 | I8: [반짝이는 상자] 상자를 여는 중... | J8: 안에 금화가 들어 있었다! | K8: 상자에서 먼지가 뿜어져 나와 콜록거렸다. | L8: 금화 +4
A9: 반짝이는 상자 | B9: 어디서나 | C9: [반짝이는 상자] 길가에 낡은 보물상자가 놓여 있다. | D9: 함정이 있는지 살핀다 | E9: 감지 | F9: 3 | G9: 12 | H9: 3 | I9: [반짝이는 상자] 상자를 살피는 중... | J9: 바늘 함정을 피해 바닥의 금화를 꺼냈다. | K9: 아무것도 찾지 못하고 시간만 흘렀다. | L9: 금화 +3
A10: 반짝이는 상자 | B10: 어디서나 | C10: [반짝이는 상자] 길가에 낡은 보물상자가 놓여 있다. | D10: 그냥 둔다 | E10: 정신 | F10: 1 | G10: 6 | H10: 1 | I10: [반짝이는 상자] 지나치는 중... | J10: 함정일지도 모르니 조용히 지나쳤다. | K10: 미련이 남아 한참 뒤돌아보았다.
A11: 숨겨진 함정 | B11: 어디서나 | C11: [숨겨진 함정] 발밑에서 딸깍 소리가 났다. 함정이다! | D11: 재빨리 몸을 날린다 | E11: 민첩 | F11: 3 | G11: 12 | H11: 3 | I11: [숨겨진 함정] 몸을 날리는 중... | J11: 아슬아슬하게 피했다! 화살이 바닥에 박혀 부르르 떨렸다. | K11: 피하다 넘어져 함정에 걸렸다! 체력이 4 깎였다.
A12: 숨겨진 함정 | B12: 어디서나 | C12: [숨겨진 함정] 발밑에서 딸깍 소리가 났다. 함정이다! | D12: 장치를 해체한다 | E12: 재주 | F12: 3 | G12: 12 | H12: 3 | I12: [숨겨진 함정] 장치를 해체하는 중... | J12: 장치를 멈추고 쓸 만한 부품까지 챙겼다. | K12: 해체하다 함정이 작동해 버렸다! 체력이 5 깎였다. | L12: 금화 +2
A13: 숨겨진 함정 | B13: 어디서나 | C13: [숨겨진 함정] 발밑에서 딸깍 소리가 났다. 함정이다! | D13: 악물고 버틴다 | E13: 근력 | F13: 2 | G13: 9 | H13: 2 | I13: [숨겨진 함정] 버티는 중... | J13: 단단한 몸으로 버티고 함정을 넘겼다. | K13: 함정에 정통으로 맞았다! 체력이 6 깎였다.
A14: 덫에 걸린 여우 | B14: 숲, 초원 | C14: [덫에 걸린 여우] 나무 사이에서 덫에 다리가 걸린 여우가 낑낑대고 있다. | D14: 덫을 풀어 준다 | E14: 재주 | F14: 3 | G14: 12 | H14: 3 | I14: [덫에 걸린 여우] 덫을 푸는 중... | J14: 덫이 풀리자 여우가 산딸기 덤불로 안내하고 사라졌다. | K14: 덫이 튀어 올라 손을 긁혔다. 여우는 겨우 빠져나갔다. 체력이 2 깎였다. | L14: 산딸기 +1
A15: 덫에 걸린 여우 | B15: 숲, 초원 | C15: [덫에 걸린 여우] 나무 사이에서 덫에 다리가 걸린 여우가 낑낑대고 있다. | D15: 달래서 진정시킨다 | E15: 정신 | F15: 2 | G15: 9 | H15: 2 | I15: [덫에 걸린 여우] 여우를 달래는 중... | J15: 여우가 얌전해졌고, 근처에서 누군가 흘린 동전을 발견했다. | K15: 여우가 놀라 날뛰는 바람에 다가갈 수 없었다. | L15: 금화 +2
A16: 덫에 걸린 여우 | B16: 숲, 초원 | C16: [덫에 걸린 여우] 나무 사이에서 덫에 다리가 걸린 여우가 낑낑대고 있다. | D16: 덫을 놓은 사냥꾼을 찾는다 | E16: 감지 | F16: 3 | G16: 12 | H16: 3 | I16: [덫에 걸린 여우] 사냥꾼의 흔적을 쫓는 중... | J16: 사냥꾼을 찾아 여우를 풀어 주게 했다. 사냥꾼이 미안하다며 사례를 했다. | K16: 흔적을 놓쳐 버렸다. | L16: 금화 +4
A17: 풀숲의 둥지 | B17: 초원, 숲 | C17: [풀숲의 둥지] 키 큰 풀숲에 커다란 새 둥지가 보인다. 어미 새는 보이지 않는다. | D17: 어미 새의 동태를 살핀다 | E17: 감지 | F17: 2 | G17: 9 | H17: 2 | I17: [풀숲의 둥지] 주변을 살피는 중... | J17: 어미 새가 멀리 있는 걸 확인하고 둥지 옆 반짝이는 동전을 주웠다. | K17: 아무것도 알아내지 못했다. | L17: 금화 +2
A18: 풀숲의 둥지 | B18: 초원, 숲 | C18: [풀숲의 둥지] 키 큰 풀숲에 커다란 새 둥지가 보인다. 어미 새는 보이지 않는다. | D18: 살금살금 다가간다 | E18: 민첩 | F18: 3 | G18: 12 | H18: 3 | I18: [풀숲의 둥지] 살금살금 다가가는 중... | J18: 둥지에 섞여 있던 금화를 슬쩍 꺼냈다! | K18: 어미 새가 돌아와 사정없이 쪼아 댔다! 체력이 3 깎였다. | L18: 금화 +4
A19: 풀숲의 둥지 | B19: 초원, 숲 | C19: [풀숲의 둥지] 키 큰 풀숲에 커다란 새 둥지가 보인다. 어미 새는 보이지 않는다. | D19: 조용히 지나간다 | E19: 정신 | F19: 1 | G19: 6 | H19: 1 | I19: [풀숲의 둥지] 조용히 지나가는 중... | J19: 둥지를 건드리지 않고 지나쳤다. | K19: 발소리에 놀란 새들이 날아올라 정신이 없었다.
A20: 물에 빠진 짐 꾸러미 | B20: 호수, 항구 마을 | C20: [물에 빠진 짐 꾸러미] 물가에 누군가 떨어뜨린 짐 꾸러미가 둥둥 떠내려간다. | D20: 헤엄쳐 건진다 | E20: 근력 | F20: 3 | G20: 12 | H20: 3 | I20: [물에 빠진 짐 꾸러미] 헤엄치는 중... | J20: 꾸러미를 건져 냈다. 안에 금화가 들어 있었다! | K20: 물살에 휩쓸려 허우적대다 겨우 나왔다. 체력이 2 깎였다. | L20: 금화 +6
A21: 물에 빠진 짐 꾸러미 | B21: 호수, 항구 마을 | C21: [물에 빠진 짐 꾸러미] 물가에 누군가 떨어뜨린 짐 꾸러미가 둥둥 떠내려간다. | D21: 긴 나뭇가지로 끌어당긴다 | E21: 재주 | F21: 3 | G21: 12 | H21: 3 | I21: [물에 빠진 짐 꾸러미] 나뭇가지로 끌어당기는 중... | J21: 나뭇가지에 걸린 꾸러미를 끌어올렸다. | K21: 나뭇가지가 툭 부러졌다. | L21: 금화 +4
A22: 물에 빠진 짐 꾸러미 | B22: 호수, 항구 마을 | C22: [물에 빠진 짐 꾸러미] 물가에 누군가 떨어뜨린 짐 꾸러미가 둥둥 떠내려간다. | D22: 떠내려올 곳을 예측한다 | E22: 지력 | F22: 3 | G22: 12 | H22: 3 | I22: [물에 빠진 짐 꾸러미] 물살을 읽는 중... | J22: 물살이 모이는 곳에서 기다렸다가 꾸러미를 주웠다. | K22: 예측이 빗나가 꾸러미가 멀리 사라졌다. | L22: 금화 +4
A23: 발밑이 꺼지는 늪 | B23: 늪지 | C23: [발밑이 꺼지는 늪] 한 발 내딛자 발이 늪 속으로 쑥 빠져들기 시작한다! | D23: 힘으로 빠져나온다 | E23: 근력 | F23: 3 | G23: 12 | H23: 3 | I23: [발밑이 꺼지는 늪] 힘껏 다리를 빼는 중... | J23: 온 힘을 다해 다리를 빼냈다. | K23: 허우적댈수록 더 깊이 빠져 한참을 고생했다. 체력이 4 깎였다.
A24: 발밑이 꺼지는 늪 | B24: 늪지 | C24: [발밑이 꺼지는 늪] 한 발 내딛자 발이 늪 속으로 쑥 빠져들기 시작한다! | D24: 침착하게 몸을 눕힌다 | E24: 정신 | F24: 3 | G24: 12 | H24: 3 | I24: [발밑이 꺼지는 늪] 몸을 눕혀 빠져나오는 중... | J24: 당황하지 않고 몸을 넓게 펴서 빠져나왔다. | K24: 겁에 질려 버둥대다 진흙을 잔뜩 먹었다. 체력이 4 깎였다.
A25: 발밑이 꺼지는 늪 | B25: 늪지 | C25: [발밑이 꺼지는 늪] 한 발 내딛자 발이 늪 속으로 쑥 빠져들기 시작한다! | D25: 덩굴을 붙잡는다 | E25: 재주 | F25: 2 | G25: 9 | H25: 2 | I25: [발밑이 꺼지는 늪] 덩굴을 붙잡는 중... | J25: 덩굴을 붙잡고 단단한 땅으로 올라섰다. | K25: 덩굴이 끊어져 늪에 다시 빠졌다. 체력이 4 깎였다.
A26: 도깨비불 | B26: 늪지, 고대 유적 | C26: [도깨비불] 안개 속에서 파란 불빛이 이리 오라는 듯 흔들린다. | D26: 불빛을 따라간다 | E26: 행운 | F26: 5 | G26: 18 | H26: 5 | I26: [도깨비불] 불빛을 쫓는 중... | J26: 불빛이 멈춘 곳에 금화 꾸러미가 묻혀 있었다! | K26: 불빛을 쫓다 진흙 구덩이에 빠졌다. 체력이 3 깎였다. | L26: 금화 +10
A27: 도깨비불 | B27: 늪지, 고대 유적 | C27: [도깨비불] 안개 속에서 파란 불빛이 이리 오라는 듯 흔들린다. | D27: 정체를 살핀다 | E27: 지력 | F27: 3 | G27: 12 | H27: 3 | I27: [도깨비불] 불빛의 정체를 살피는 중... | J27: 썩은 독초에서 나는 빛이었다. 쓸 만한 독초를 챙겼다. | K27: 정체를 알 수 없어 등골이 오싹했다. | L27: 독초 +1
A28: 도깨비불 | B28: 늪지, 고대 유적 | C28: [도깨비불] 안개 속에서 파란 불빛이 이리 오라는 듯 흔들린다. | D28: 눈을 감고 지나간다 | E28: 정신 | F28: 2 | G28: 9 | H28: 2 | I28: [도깨비불] 유혹을 뿌리치는 중... | J28: 불빛의 유혹을 뿌리치고 길을 지켰다. | K28: 불빛에 홀려 한참 엉뚱한 곳을 헤맸다.
A29: 무너지는 천장 | B29: 동굴(북), 동굴(남), 고대 유적 | C29: [무너지는 천장] 우르릉! 머리 위에서 돌가루가 떨어지기 시작한다. | D29: 재빨리 빠져나간다 | E29: 민첩 | F29: 3 | G29: 12 | H29: 3 | I29: [무너지는 천장] 출구로 달리는 중... | J29: 돌이 쏟아지기 직전에 빠져나왔다! | K29: 떨어지는 돌에 어깨를 맞았다! 체력이 5 깎였다.
A30: 무너지는 천장 | B30: 동굴(북), 동굴(남), 고대 유적 | C30: [무너지는 천장] 우르릉! 머리 위에서 돌가루가 떨어지기 시작한다. | D30: 기둥을 받친다 | E30: 근력 | F30: 5 | G30: 18 | H30: 5 | I30: [무너지는 천장] 기둥을 받치는 중... | J30: 무너지려는 기둥을 받쳐 길을 지켜 냈다. | K30: 기둥과 함께 쓰러지고 말았다! 체력이 5 깎였다.
A31: 무너지는 천장 | B31: 동굴(북), 동굴(남), 고대 유적 | C31: [무너지는 천장] 우르릉! 머리 위에서 돌가루가 떨어지기 시작한다. | D31: 안전한 틈을 찾는다 | E31: 감지 | F31: 3 | G31: 12 | H31: 3 | I31: [무너지는 천장] 균열을 살피는 중... | J31: 균열이 없는 바위 틈에 몸을 숨겼다. | K31: 숨은 곳에도 돌이 떨어졌다! 체력이 5 깎였다.
A32: 고대 문양 석판 | B32: 고대 유적, 동굴(남) | C32: [고대 문양 석판] 길가에 알 수 없는 문양이 빼곡히 새겨진 석판이 서 있다. | D32: 문양을 해독한다 | E32: 지력 | F32: 5 | G32: 18 | H32: 5 | I32: [고대 문양 석판] 문양을 해독하는 중... | J32: 숨겨진 보물의 위치를 읽어 내 금화를 찾았다! | K32: 머리만 지끈거렸다. | L32: 금화 +12
A33: 고대 문양 석판 | B33: 고대 유적, 동굴(남) | C33: [고대 문양 석판] 길가에 알 수 없는 문양이 빼곡히 새겨진 석판이 서 있다. | D33: 석판 조각을 떼어 낸다 | E33: 재주 | F33: 3 | G33: 12 | H33: 3 | I33: [고대 문양 석판] 석판을 다듬는 중... | J33: 깨지지 않게 조각 하나를 떼어 냈다. | K33: 석판이 엉뚱하게 갈라져 쓸모없어졌다. | L33: 유물 조각 +1
A34: 고대 문양 석판 | B34: 고대 유적, 동굴(남) | C34: [고대 문양 석판] 길가에 알 수 없는 문양이 빼곡히 새겨진 석판이 서 있다. | D34: 문양에 손을 얹는다 | E34: 행운 | F34: 3 | G34: 12 | H34: 3 | I34: [고대 문양 석판] 문양에 손을 얹는 중... | J34: 석판이 빛나더니 금화가 쏟아졌다! | K34: 찌릿한 기운이 온몸을 훑고 지나갔다. 체력이 3 깎였다. | L34: 금화 +8
A35: 눈사태 조짐 | B35: 산(서), 산(동), 설원, 눈 마을 | C35: [눈사태 조짐] 산비탈에서 쩌억 하는 소리와 함께 눈 덩어리가 미끄러지기 시작한다! | D35: 바위 뒤로 피한다 | E35: 민첩 | F35: 3 | G35: 12 | H35: 3 | I35: [눈사태 조짐] 바위 뒤로 달리는 중... | J35: 큰 바위 뒤로 몸을 날려 눈사태를 피했다. | K35: 눈더미에 휩쓸렸다! 체력이 5 깎였다.
A36: 눈사태 조짐 | B36: 산(서), 산(동), 설원, 눈 마을 | C36: [눈사태 조짐] 산비탈에서 쩌억 하는 소리와 함께 눈 덩어리가 미끄러지기 시작한다! | D36: 소리로 방향을 읽는다 | E36: 감지 | F36: 3 | G36: 12 | H36: 3 | I36: [눈사태 조짐] 소리에 귀 기울이는 중... | J36: 눈사태가 비껴가는 쪽을 알아차리고 피했다. | K36: 방향을 잘못 읽었다! 체력이 5 깎였다.
A37: 눈사태 조짐 | B37: 산(서), 산(동), 설원, 눈 마을 | C37: [눈사태 조짐] 산비탈에서 쩌억 하는 소리와 함께 눈 덩어리가 미끄러지기 시작한다! | D37: 몸을 낮추고 버틴다 | E37: 근력 | F37: 4 | G37: 15 | H37: 4 | I37: [눈사태 조짐] 몸을 낮추고 버티는 중... | J37: 몸을 낮게 웅크려 눈더미를 버텨 냈다. | K37: 눈에 파묻혀 한참을 헤어나지 못했다. 체력이 5 깎였다.
A38: 얼어붙은 여행자 | B38: 설원, 눈 마을, 산(동) | C38: [얼어붙은 여행자] 눈밭에 웅크린 여행자가 덜덜 떨고 있다. | D38: 모닥불을 피워 준다 | E38: 재주 | F38: 3 | G38: 12 | H38: 3 | I38: [얼어붙은 여행자] 불을 피우는 중... | J38: 불을 쬐고 기운을 차린 여행자가 감사의 표시로 금화를 건넸다. | K38: 젖은 나무만 연기를 피웠다... | L38: 금화 +6
A39: 얼어붙은 여행자 | B39: 설원, 눈 마을, 산(동) | C39: [얼어붙은 여행자] 눈밭에 웅크린 여행자가 덜덜 떨고 있다. | D39: 업고 마을까지 간다 | E39: 근력 | F39: 3 | G39: 12 | H39: 3 | I39: [얼어붙은 여행자] 여행자를 업고 걷는 중... | J39: 마을 사람들이 고마워하며 사례금을 모아 주었다. | K39: 무게에 지쳐 함께 주저앉고 말았다. 체력이 2 깎였다. | L39: 금화 +10
A40: 얼어붙은 여행자 | B40: 설원, 눈 마을, 산(동) | C40: [얼어붙은 여행자] 눈밭에 웅크린 여행자가 덜덜 떨고 있다. | D40: 계속 말을 걸어 깨운다 | E40: 정신 | F40: 3 | G40: 12 | H40: 3 | I40: [얼어붙은 여행자] 말을 거는 중... | J40: 여행자가 정신을 차리고 스스로 일어났다. 고맙다며 금화를 주었다. | K40: 여행자가 다시 눈을 감아 버렸다. 결국 지나가던 썰매꾼이 데려갔다. | L40: 금화 +5
...

Sheet 의뢰
A1: 순서 | B1: 제목 | C1: 받는 곳 | D1: 의뢰인 | E1: 목표 | F1: 보고하는 곳 | G1: 보상 금화 | H1: 보상 물건 | I1: 의뢰 대사 (타자 효과) | J1: 목표를 못 채우고 보고할 때 | K1: 완료 대사 (타자 효과)
A2: 1 | B2: 모험을 시작하는 너에게 | C2: 시작 마을 | D2: 여관 주인 알토 | E2: 상점에서 무기 1종 구매 | F2: 시작 마을 | G2: 8 | I2: 여관 주인, 알토 | 아, 그 소문을 듣고 왔다면... 이제 막 모험을 시작했겠구나. 물론 이 알토가 도와주어야겠지! 여관 주인, 알토 | 대신, 좀 있다 부탁 하나만 들어 주렴. 걱정 마, 어려운 일은 아닐 거란다. 알토가 자신의 턱에 손을 올리고, 당신의 모습을 이리저리 훑는다. 여관 주인, 알토 | 우선은 무기를 마련하는 게 좋겠어. 상점 '넛츠 프레젠트'로 가서, 네 마음에 드는 무기, 혹은 네 대신 싸워 줄 아이를 데리고 오렴. 여관 주인, 알토 | 잘 사서 돌아오면 보상을 줄 테니, 어서 가 보렴. | J2: 여관 주인, 알토 | 으응? ...맨손으로 싸우겠다고? 여관 주인, 알토 | 호호, 안 되지. 아가, 무기를 가져오렴. 잘 싸우려면 무기가 꼭 필요할 거란다. 여관 주인, 알토 | 상점으로 가서, 네가 원하는 무기를 사오는 거야. 자, 어서. | K2: 여관 주인, 알토 | 잘했어요! 이건 보상이란다, 무기 값에 보태도록 하렴. 여관 주인, 알토 | 그러면, 잠시 시간을 내 주겠니? 정식으로 맡기고 싶은 의뢰가 있단다.
A3: 2 | B3: 꾸러미 배달 | C3: 시작 마을 | D3: 여관 주인 알토 | E3: 상인 포체에게 알토의 꾸러미 전달 | F3: 항구 마을 | G3: 12 | I3: [여관 주인 알토] 그럼 이제 부탁 하나만 들어 줄래요? 서쪽 항구 마을의 상인 포체에게 이 꾸러미를 전해 줘야 하는데, 손님이 많아 여관을 비울 수가 없어서요. 초원에서 산을 넘어 호수를 지나는 초록색 길이 가장 안전하답니다. 늪지를 지나는 빨간 길은 빠르지만 위험해요. | J3: (배달은 목적지에 도착하면 바로 보고 가능) | K3: [상인 포체] 포체가 꾸러미를 받아 들고 환하게 웃는다. "알토가 보낸 거로군! 먼 길 수고했소. 이건 수고비요."
A4: 3 | B4: 몬스터 퇴치 | C4: 항구 마을 | D4: 상인 포체 | E4: 몬스터 2마리 처치 | F4: 항구 마을 | G4: 20 | H4: 지금 쓰는 분류의 2단계 무기 | I4: [상인 포체] 그런데 마침 일손이 필요하던 참이오. 요즘 이 근방에 몬스터가 들끓어서 배를 띄울 수가 없어 고민이오. 길에서 마주치는 몬스터를 2마리만 쓰러뜨려 주지 않겠소? 해내면 지금 쓰는 무기보다 한 단계 좋은 것을 하나 구해 주겠소. 위험한 길일수록 자주 만날 거요. 싸우다 위험하면 도망쳐도 좋소. | J4: [상인 포체] 아직 멀었소. 길을 오가다 보면 몬스터를 만날 거요. 위험한 길일수록 자주 나타난다오. | K4: [상인 포체] "덕분에 한시름 놓았소! 이제 항구에서 배가 뜰 수 있겠군. 약속대로 (지금 쓰는 분류의 2단계 무기)를 받으시오. 지금 쓰는 것보다 한결 수월할 거요."
A5: 4 | B5: 배에 실을 약초 | C5: 항구 마을 | D5: 상인 포체 | E5: 약초 4개 모으기 | F5: 항구 마을 | G5: 12 | H5: 낚싯대 | I5: [상인 포체] 배에 실을 약상자가 텅 비었소. 늪지나 산에서 약초를 4개만 구해 주겠소? 약초 채집을 하면 독초가 섞여 나오기도 하니 잘 골라 오시오. 사례로 낚싯대를 하나 주겠소. | J5: [상인 포체] 약초는 늪지, 서쪽과 동쪽 산, 설원에서 '약초 채집'으로 얻을 수 있소. 손재주(재주)가 좋을수록 잘 딴다오. | K5: [상인 포체] "훌륭하오! 약속대로 낚싯대를 주지. 호수나 해변, 동굴의 물웅덩이에서 낚시를 해 보시오. 금린어를 낚으면 이 항구에서 비싸게 사 주겠소."
A6: 5 | B6: 눈 마을에 편지 전하기 | C6: 항구 마을 | D6: 상인 포체 | E6: 상인 헬라에게 포체의 편지 전달 | F6: 눈 마을 | G6: 30 | I6: [상인 포체] 마지막으로 하나만 더 부탁하겠소. 북동쪽 눈 마을의 헬라에게 이 편지를 전해 주시오. 시작 마을 위 숲에서 동쪽 산을 넘거나, 서쪽 산에서 협곡과 설원을 지나 가는 길이 있소. 먼 길이니 대장장이 헤일리에게 장비를 맞추고 훈련장에서 몸을 단련한 뒤 떠나는 게 좋겠소. | J6: (배달은 목적지에 도착하면 바로 보고 가능) | K6: [상인 헬라] 헬라가 편지를 읽고 고개를 끄덕인다. "포체가 보냈군요. 먼 길 오느라 고생했어요. 자, 수고비예요."
A7: 6 | B7: 설원 늑대 퇴치 | C7: 눈 마을 | D7: 상인 헬라 | E7: 설원 늑대 2마리 처치 | F7: 눈 마을 | G7: 40 | I7: [상인 헬라] 마침 잘 오셨어요. 요즘 설원 늑대가 마을 곳간을 노려서 고민이에요. 두 마리만 쓰러뜨려 주세요. 그놈들은 하울링으로 동료를 부르니, 재주로 덫을 놓아 하울링을 막는 게 좋아요. 설원은 마을 북쪽이에요. | J7: [상인 헬라] 설원 늑대는 설원과 눈 마을 근처에서 나타나요. 하울링은 재주로 막을 수 있어요. | K7: [상인 헬라] "이제 마을이 조용해지겠네요! 정말 고마워요."
A8: 7 | B8: 해충 퇴치약 | C8: 눈 마을 | D8: 상인 헬라 | E8: 독초 3개 모으기 | F8: 눈 마을 | G8: 30 | H8: 마법 주사위 | I8: [상인 헬라] 한 가지만 더 부탁할게요. 겨울 동안 곳간에 벌레가 끼지 않게 퇴치약을 만들어야 해요. 독초를 3개만 구해 주세요. 이 마을은 독초를 비싸게 사 주니 남는 건 팔아도 좋아요. | J8: [상인 헬라] 독초는 '약초 채집'을 하다 보면 섞여 나와요. 설원이나 동쪽 산에서 찾아보세요. | K8: [상인 헬라] "이걸로 겨울을 날 수 있겠어요! 감사의 표시로 이 마법 주사위를 드릴게요. 이제 당신은 어엿한 모험가예요. 다만 관문 너머 로렌시아 제국은 아직 출입이 금지되어 있으니, 섬 안을 자유롭게 탐험해 보세요!"
A10: 의뢰 대사 아래에는 '의뢰: 제목 / 목표 / 보상'이, 완료 대사 아래에는 '의뢰 완료 / 보상'이 붙음. 2번째 의뢰 보상 무기는 지금 쓰는 무기 분류에 맞춰 바뀜.

Sheet 전투
A1: 이름 | B1: 등장 | C1: 체력 | D1: 공격력 | E1: 등급 | F1: 공격 단계 | G1: 공격 목표 | H1: 방어 단계 | I1: 방어 목표 | J1: 도망 추가(flee) | K1: 도망 단계 | L1: 도망 목표 | M1: 공격 성공(+2) | N1: 방어 성공(+2) | O1: 도망 성공(+2) | P1: 적 공격 1회 기대 피해(+2) | Q1: 고유 기믹 | R1: 기믹 효과 | S1: 대응 스탯 | T1: 대응 단계 | U1: 대응 목표 | V1: 대응 성공 문장 | W1: 대응 실패 문장 | X1: 출현 장소
A2: 슬라임 | B2: 슬라임이 덤벼든다! | C2: 8 | D2: 2 | E2: 0 | F2: 1 | G2: {=INDEX('규칙'!$C$26:$C$30,F2)} -> 6 | H2: 1 | I2: {=INDEX(난이도[목표 달성치],H2)} -> 6 | J2: 0 | K2: =MIN(5,2+J2) -> 2 | L2: {=INDEX(난이도[목표 달성치],K2)} -> 9 | M2: =(MAX(0,MIN(18,20-MAX(2,G2-2)))+1)/20 -> 0.85 | N2: =(MAX(0,MIN(18,20-MAX(2,I2-2)))+1)/20 -> 0.85 | O2: =(MAX(0,MIN(18,20-MAX(2,L2-2)))+1)/20 -> 0.7 | P2: =D2*(1-N2) -> 0.3 | U2: {=IF(T2="","",INDEX(난이도[목표 달성치],T2))} | X2: 시작 마을, 숲, 호수
A3: 동굴 박쥐 | B3: 동굴 박쥐가 덤벼든다! | C3: 6 | D3: 2 | E3: 0 | F3: 2 | G3: {=INDEX('규칙'!$C$26:$C$30,F3)} -> 9 | H3: 1 | I3: {=INDEX(난이도[목표 달성치],H3)} -> 6 | J3: 0 | K3: =MIN(5,2+J3) -> 2 | L3: {=INDEX(난이도[목표 달성치],K3)} -> 9 | M3: =(MAX(0,MIN(18,20-MAX(2,G3-2)))+1)/20 -> 0.7 | N3: =(MAX(0,MIN(18,20-MAX(2,I3-2)))+1)/20 -> 0.85 | O3: =(MAX(0,MIN(18,20-MAX(2,L3-2)))+1)/20 -> 0.7 | P3: =D3*(1-N3) -> 0.3 | U3: {=IF(T3="","",INDEX(난이도[목표 달성치],T3))} | X3: 동굴(북), 동굴(남)
A4: 게 | B4: 게가 덤벼든다! | C4: 7 | D4: 2 | E4: 0 | F4: 2 | G4: {=INDEX('규칙'!$C$26:$C$30,F4)} -> 9 | H4: 1 | I4: {=INDEX(난이도[목표 달성치],H4)} -> 6 | J4: 0 | K4: =MIN(5,2+J4) -> 2 | L4: {=INDEX(난이도[목표 달성치],K4)} -> 9 | M4: =(MAX(0,MIN(18,20-MAX(2,G4-2)))+1)/20 -> 0.7 | N4: =(MAX(0,MIN(18,20-MAX(2,I4-2)))+1)/20 -> 0.85 | O4: =(MAX(0,MIN(18,20-MAX(2,L4-2)))+1)/20 -> 0.7 | P4: =D4*(1-N4) -> 0.3 | U4: {=IF(T4="","",INDEX(난이도[목표 달성치],T4))} | X4: 항구 마을, 해변
A5: 갈매기 떼 | B5: 갈매기 떼가 덤벼든다! | C5: 6 | D5: 2 | E5: 0 | F5: 2 | G5: {=INDEX('규칙'!$C$26:$C$30,F5)} -> 9 | H5: 1 | I5: {=INDEX(난이도[목표 달성치],H5)} -> 6 | J5: 1 | K5: =MIN(5,2+J5) -> 3 | L5: {=INDEX(난이도[목표 달성치],K5)} -> 12 | M5: =(MAX(0,MIN(18,20-MAX(2,G5-2)))+1)/20 -> 0.7 | N5: =(MAX(0,MIN(18,20-MAX(2,I5-2)))+1)/20 -> 0.85 | O5: =(MAX(0,MIN(18,20-MAX(2,L5-2)))+1)/20 -> 0.55 | P5: =D5*(1-N5) -> 0.3 | U5: {=IF(T5="","",INDEX(난이도[목표 달성치],T5))} | X5: 해변
A6: 고블린 | B6: 고블린이 덤벼든다! | C6: 10 | D6: 3 | E6: 1 | F6: 2 | G6: {=INDEX('규칙'!$C$26:$C$30,F6)} -> 9 | H6: 2 | I6: {=INDEX(난이도[목표 달성치],H6)} -> 9 | J6: 1 | K6: =MIN(5,2+J6) -> 3 | L6: {=INDEX(난이도[목표 달성치],K6)} -> 12 | M6: =(MAX(0,MIN(18,20-MAX(2,G6-2)))+1)/20 -> 0.7 | N6: =(MAX(0,MIN(18,20-MAX(2,I6-2)))+1)/20 -> 0.7 | O6: =(MAX(0,MIN(18,20-MAX(2,L6-2)))+1)/20 -> 0.55 | P6: =D6*(1-N6) -> 0.9 | U6: {=IF(T6="","",INDEX(난이도[목표 달성치],T6))} | X6: 숲, 동굴(북), 관문
A7: 멧돼지 | B7: 멧돼지가 덤벼든다! | C7: 12 | D7: 3 | E7: 1 | F7: 2 | G7: {=INDEX('규칙'!$C$26:$C$30,F7)} -> 9 | H7: 3 | I7: {=INDEX(난이도[목표 달성치],H7)} -> 12 | J7: 1 | K7: =MIN(5,2+J7) -> 3 | L7: {=INDEX(난이도[목표 달성치],K7)} -> 12 | M7: =(MAX(0,MIN(18,20-MAX(2,G7-2)))+1)/20 -> 0.7 | N7: =(MAX(0,MIN(18,20-MAX(2,I7-2)))+1)/20 -> 0.55 | O7: =(MAX(0,MIN(18,20-MAX(2,L7-2)))+1)/20 -> 0.55 | P7: =D7*(1-N7) -> 1.35 | U7: {=IF(T7="","",INDEX(난이도[목표 달성치],T7))} | X7: 숲, 초원
A8: 독사 | B8: 독사가 덤벼든다! | C8: 7 | D8: 3 | E8: 1 | F8: 3 | G8: {=INDEX('규칙'!$C$26:$C$30,F8)} -> 12 | H8: 2 | I8: {=INDEX(난이도[목표 달성치],H8)} -> 9 | J8: 1 | K8: =MIN(5,2+J8) -> 3 | L8: {=INDEX(난이도[목표 달성치],K8)} -> 12 | M8: =(MAX(0,MIN(18,20-MAX(2,G8-2)))+1)/20 -> 0.55 | N8: =(MAX(0,MIN(18,20-MAX(2,I8-2)))+1)/20 -> 0.7 | O8: =(MAX(0,MIN(18,20-MAX(2,L8-2)))+1)/20 -> 0.55 | P8: =D8*(1-N8) -> 0.9 | U8: {=IF(T8="","",INDEX(난이도[목표 달성치],T8))} | X8: 늪지
A9: 전갈 | B9: 전갈이 덤벼든다! | C9: 9 | D9: 3 | E9: 1 | F9: 3 | G9: {=INDEX('규칙'!$C$26:$C$30,F9)} -> 12 | H9: 2 | I9: {=INDEX(난이도[목표 달성치],H9)} -> 9 | J9: 1 | K9: =MIN(5,2+J9) -> 3 | L9: {=INDEX(난이도[목표 달성치],K9)} -> 12 | M9: =(MAX(0,MIN(18,20-MAX(2,G9-2)))+1)/20 -> 0.55 | N9: =(MAX(0,MIN(18,20-MAX(2,I9-2)))+1)/20 -> 0.7 | O9: =(MAX(0,MIN(18,20-MAX(2,L9-2)))+1)/20 -> 0.55 | P9: =D9*(1-N9) -> 0.9 | U9: {=IF(T9="","",INDEX(난이도[목표 달성치],T9))} | X9: 협곡, 동굴(남), 사막
A10: 모래 도마뱀 | B10: 모래 도마뱀이 덤벼든다! | C10: 9 | D10: 3 | E10: 1 | F10: 3 | G10: {=INDEX('규칙'!$C$26:$C$30,F10)} -> 12 | H10: 2 | I10: {=INDEX(난이도[목표 달성치],H10)} -> 9 | J10: 1 | K10: =MIN(5,2+J10) -> 3 | L10: {=INDEX(난이도[목표 달성치],K10)} -> 12 | M10: =(MAX(0,MIN(18,20-MAX(2,G10-2)))+1)/20 -> 0.55 | N10: =(MAX(0,MIN(18,20-MAX(2,I10-2)))+1)/20 -> 0.7 | O10: =(MAX(0,MIN(18,20-MAX(2,L10-2)))+1)/20 -> 0.55 | P10: =D10*(1-N10) -> 0.9 | U10: {=IF(T10="","",INDEX(난이도[목표 달성치],T10))} | X10: 사막, 오아시스
A11: 늑대 | B11: 늑대가 덤벼든다! | C11: 11 | D11: 3 | E11: 1 | F11: 2 | G11: {=INDEX('규칙'!$C$26:$C$30,F11)} -> 9 | H11: 3 | I11: {=INDEX(난이도[목표 달성치],H11)} -> 12 | J11: 2 | K11: =MIN(5,2+J11) -> 4 | L11: {=INDEX(난이도[목표 달성치],K11)} -> 15 | M11: =(MAX(0,MIN(18,20-MAX(2,G11-2)))+1)/20 -> 0.7 | N11: =(MAX(0,MIN(18,20-MAX(2,I11-2)))+1)/20 -> 0.55 | O11: =(MAX(0,MIN(18,20-MAX(2,L11-2)))+1)/20 -> 0.4 | P11: =D11*(1-N11) -> 1.35 | U11: {=IF(T11="","",INDEX(난이도[목표 달성치],T11))} | X11: 초원, 산(서), 산(동)
A12: 악어 | B12: 악어가 덤벼든다! | C12: 15 | D12: 4 | E12: 2 | F12: 3 | G12: {=INDEX('규칙'!$C$26:$C$30,F12)} -> 12 | H12: 2 | I12: {=INDEX(난이도[목표 달성치],H12)} -> 9 | J12: 2 | K12: =MIN(5,2+J12) -> 4 | L12: {=INDEX(난이도[목표 달성치],K12)} -> 15 | M12: =(MAX(0,MIN(18,20-MAX(2,G12-2)))+1)/20 -> 0.55 | N12: =(MAX(0,MIN(18,20-MAX(2,I12-2)))+1)/20 -> 0.7 | O12: =(MAX(0,MIN(18,20-MAX(2,L12-2)))+1)/20 -> 0.4 | P12: =D12*(1-N12) -> 1.2 | Q12: 물속 매복 | R12: 물속에 숨어 내 공격이 더 잘 빗나간다 (공격 난이도 한 단계 위) | S12: 재주 | T12: 2 | U12: {=IF(T12="","",INDEX(난이도[목표 달성치],T12))} -> 9 | V12: 미끼 덫으로 악어를 물 밖으로 끌어냈다! | W12: 미끼를 놓쳤고 악어가 달려든다! | X12: 늪지, 오아시스
A13: 해골 병사 | B13: 해골 병사가 덤벼든다! | C13: 13 | D13: 3 | E13: 2 | F13: 3 | G13: {=INDEX('규칙'!$C$26:$C$30,F13)} -> 12 | H13: 2 | I13: {=INDEX(난이도[목표 달성치],H13)} -> 9 | J13: 2 | K13: =MIN(5,2+J13) -> 4 | L13: {=INDEX(난이도[목표 달성치],K13)} -> 15 | M13: =(MAX(0,MIN(18,20-MAX(2,G13-2)))+1)/20 -> 0.55 | N13: =(MAX(0,MIN(18,20-MAX(2,I13-2)))+1)/20 -> 0.7 | O13: =(MAX(0,MIN(18,20-MAX(2,L13-2)))+1)/20 -> 0.4 | P13: =D13*(1-N13) -> 0.9 | Q13: 저주 오라 | R13: 불길한 기운에 내 모든 판정이 -1 된다 | S13: 행운 | T13: 2 | U13: {=IF(T13="","",INDEX(난이도[목표 달성치],T13))} -> 9 | V13: 행운을 믿고 징크스를 깨뜨렸다! | W13: 불운이 더 짙어진다... | X13: 고대 유적
A14: 설원 늑대 | B14: 설원 늑대가 덤벼든다! | C14: 14 | D14: 4 | E14: 2 | F14: 2 | G14: {=INDEX('규칙'!$C$26:$C$30,F14)} -> 9 | H14: 3 | I14: {=INDEX(난이도[목표 달성치],H14)} -> 12 | J14: 3 | K14: =MIN(5,2+J14) -> 5 | L14: {=INDEX(난이도[목표 달성치],K14)} -> 18 | M14: =(MAX(0,MIN(18,20-MAX(2,G14-2)))+1)/20 -> 0.7 | N14: =(MAX(0,MIN(18,20-MAX(2,I14-2)))+1)/20 -> 0.55 | O14: =(MAX(0,MIN(18,20-MAX(2,L14-2)))+1)/20 -> 0.25 | P14: =D14*(1-N14) -> 1.8 | Q14: 하울링 | R14: 2라운드마다 동료가 달려들어 추가로 공격한다 | S14: 재주 | T14: 2 | U14: {=IF(T14="","",INDEX(난이도[목표 달성치],T14))} -> 9 | V14: 올가미 덫으로 무리의 길목을 막았다! | W14: 덫이 허탕을 쳤고 울음이 더 커진다! | X14: 설원, 눈 마을
A15: 곰 | B15: 곰이 덤벼든다! | C15: 18 | D15: 4 | E15: 3 | F15: 3 | G15: {=INDEX('규칙'!$C$26:$C$30,F15)} -> 12 | H15: 3 | I15: {=INDEX(난이도[목표 달성치],H15)} -> 12 | J15: 3 | K15: =MIN(5,2+J15) -> 5 | L15: {=INDEX(난이도[목표 달성치],K15)} -> 18 | M15: =(MAX(0,MIN(18,20-MAX(2,G15-2)))+1)/20 -> 0.55 | N15: =(MAX(0,MIN(18,20-MAX(2,I15-2)))+1)/20 -> 0.55 | O15: =(MAX(0,MIN(18,20-MAX(2,L15-2)))+1)/20 -> 0.25 | P15: =D15*(1-N15) -> 1.8 | Q15: 광폭화 | R15: 3라운드마다 곰의 공격력이 +1씩 오른다 (최대 +3) | S15: 지력 | T15: 3 | U15: {=IF(T15="","",INDEX(난이도[목표 달성치],T15))} -> 12 | V15: 먹이를 던져 곰을 진정시켰다! | W15: 곰이 더 흥분해 덤벼든다! | X15: 산(서), 산(동), 협곡, 설원
A16: 골렘 | B16: 골렘이 덤벼든다! | C16: 18 | D16: 4 | E16: 3 | F16: 4 | G16: {=INDEX('규칙'!$C$26:$C$30,F16)} -> 15 | H16: 2 | I16: {=INDEX(난이도[목표 달성치],H16)} -> 9 | J16: 3 | K16: =MIN(5,2+J16) -> 5 | L16: {=INDEX(난이도[목표 달성치],K16)} -> 18 | M16: =(MAX(0,MIN(18,20-MAX(2,G16-2)))+1)/20 -> 0.4 | N16: =(MAX(0,MIN(18,20-MAX(2,I16-2)))+1)/20 -> 0.7 | O16: =(MAX(0,MIN(18,20-MAX(2,L16-2)))+1)/20 -> 0.25 | P16: =D16*(1-N16) -> 1.2 | Q16: 돌 갑옷 | R16: 단단한 돌 갑옷 때문에 내 공격 피해가 2 줄어든다 | S16: 감지 | T16: 3 | U16: {=IF(T16="","",INDEX(난이도[목표 달성치],T16))} -> 12 | V16: 갑옷의 균열을 찾아냈다! 갑옷이 부서진다! | W16: 균열을 찾지 못했다. 골렘이 반격한다! | X16: 고대 유적
A18: 공격 단계: 작고 빠르거나 단단하면 높음 / 방어 단계: 힘이 세거나 덮쳐 오면 높음. 도망 단계 = 2 + flee(없으면 등급), 최대 5.
A19: 몬스터의 공격은 항상 명중하고, 방어에 실패하면 공격력만큼 전투 HP가 깎임. 성공 확률은 판정 보정 +2(스탯 6~8, 장비 없음) 기준.
A20: 물속 매복(악어)은 기믹이 남아 있는 동안 공격 단계 +1, 저주 오라(해골 병사)는 내 모든 판정 -1.
A22: 공통 전투 문장
A23: 공격 명중 | B23: [공격·{스탯}] 🎲 … : 명중! {피해} 피해를 줬다.
A24: 공격 빗나감 | B24: [공격·{스탯}] 🎲 … : 빗나갔다...
A25: 방어 성공 | B25: [방어] 🎲 … : {몬스터}의 공격을 막아냈다!
A26: 방어 실패 | B26: [방어] 🎲 … : 막지 못했다! {몬스터}에게 {피해} 피해를 입었다.
A27: 기믹 대응 성공 | B27: [{기믹} 대응] 🎲 … : 파훼 성공! {대응 성공 문장}
A28: 기믹 대응 실패 | B28: [{기믹} 대응] 🎲 … : 실패... {대응 실패 문장}
A29: 하울링 추가 공격 | B29: [하울링] 동료 늑대가 달려든다!
A30: 도망 확인 팝업 | B30: 정말 도망치시겠습니까? / 도망 판정: {난이도} (민첩)
A31: 도망 성공 | B31: [도망] 🎲 … : 성공! → 전력으로 달려 무사히 도망쳤다!
A32: 도망 실패 | B32: [도망] 🎲 … : 실패! 길이 막혔다.
A33: 승리 | B33: {몬스터}를 쓰러뜨렸다! 승리! 금화 {N}닢을 얻었다.
A34: 패배 | B34: 쓰러지고 말았다... 체력이 5 깎였다. 간신히 몸을 일으켰다.

Sheet 채집_보물
A1: 장소 | B1: 종류 | C1: 행동 | D1: 얻는 재료 | E1: 판정 스탯 | F1: 단계 | G1: 목표 | H1: 시간(초) | I1: 필요 도구 | J1: 보물 금화 | K1: 성공 확률(+2)
A2: 시작 마을 | B2: 숨겨진 보물 | C2: 마을 구석 살펴보기 | E2: 감지 | F2: 3 | G2: {=INDEX('규칙'!$C$26:$C$30,F2)} -> 12 | H2: {=INDEX('규칙'!$E$26:$E$30,F2)} -> 3 | J2: 15 | K2: =(MAX(0,MIN(18,20-MAX(2,G2-2)))+1)/20 -> 0.55
A3: 숲 | B3: 채집 | C3: 열매 따기 | D3: 산딸기 65% / 나무 열매 35% | E3: 재주 | F3: 1 | G3: {=INDEX('규칙'!$C$26:$C$30,F3)} -> 6 | H3: {=INDEX('규칙'!$E$26:$E$30,F3)} -> 1 | K3: =(MAX(0,MIN(18,20-MAX(2,G3-2)))+1)/20 -> 0.85
A4: 숲 | B4: 채집 | C4: 버섯 따기 | D4: 버섯 65% / 독버섯 35% | E4: 재주 | F4: 2 | G4: {=INDEX('규칙'!$C$26:$C$30,F4)} -> 9 | H4: {=INDEX('규칙'!$E$26:$E$30,F4)} -> 2 | K4: =(MAX(0,MIN(18,20-MAX(2,G4-2)))+1)/20 -> 0.7
A5: 초원 | B5: 채집 | C5: 버섯 따기 | D5: 버섯 65% / 독버섯 35% | E5: 재주 | F5: 2 | G5: {=INDEX('규칙'!$C$26:$C$30,F5)} -> 9 | H5: {=INDEX('규칙'!$E$26:$E$30,F5)} -> 2 | K5: =(MAX(0,MIN(18,20-MAX(2,G5-2)))+1)/20 -> 0.7
A6: 초원 | B6: 채집 | C6: 열매 따기 | D6: 산딸기 65% / 나무 열매 35% | E6: 재주 | F6: 1 | G6: {=INDEX('규칙'!$C$26:$C$30,F6)} -> 6 | H6: {=INDEX('규칙'!$E$26:$E$30,F6)} -> 1 | K6: =(MAX(0,MIN(18,20-MAX(2,G6-2)))+1)/20 -> 0.85
A7: 호수 | B7: 채집 | C7: 낚시하기 | D7: 회어 70% / 금린어 30% | E7: 재주 | F7: 2 | G7: {=INDEX('규칙'!$C$26:$C$30,F7)} -> 9 | H7: {=INDEX('규칙'!$E$26:$E$30,F7)} -> 2 | I7: 낚싯대 | K7: =(MAX(0,MIN(18,20-MAX(2,G7-2)))+1)/20 -> 0.7
A8: 산(서) | B8: 채집 | C8: 약초 채집 | D8: 약초 65% / 독초 35% | E8: 재주 | F8: 2 | G8: {=INDEX('규칙'!$C$26:$C$30,F8)} -> 9 | H8: {=INDEX('규칙'!$E$26:$E$30,F8)} -> 2 | K8: =(MAX(0,MIN(18,20-MAX(2,G8-2)))+1)/20 -> 0.7
A9: 산(서) | B9: 채집 | C9: 버섯 따기 | D9: 버섯 65% / 독버섯 35% | E9: 재주 | F9: 2 | G9: {=INDEX('규칙'!$C$26:$C$30,F9)} -> 9 | H9: {=INDEX('규칙'!$E$26:$E$30,F9)} -> 2 | K9: =(MAX(0,MIN(18,20-MAX(2,G9-2)))+1)/20 -> 0.7
A10: 산(서) | B10: 숨겨진 보물 | C10: 정상 근처 살펴보기 | E10: 감지 | F10: 3 | G10: {=INDEX('규칙'!$C$26:$C$30,F10)} -> 12 | H10: {=INDEX('규칙'!$E$26:$E$30,F10)} -> 3 | J10: 12 | K10: =(MAX(0,MIN(18,20-MAX(2,G10-2)))+1)/20 -> 0.55
A11: 산(동) | B11: 채집 | C11: 약초 채집 | D11: 약초 65% / 독초 35% | E11: 재주 | F11: 2 | G11: {=INDEX('규칙'!$C$26:$C$30,F11)} -> 9 | H11: {=INDEX('규칙'!$E$26:$E$30,F11)} -> 2 | K11: =(MAX(0,MIN(18,20-MAX(2,G11-2)))+1)/20 -> 0.7
A12: 늪지 | B12: 채집 | C12: 약초 채집 | D12: 약초 65% / 독초 35% | E12: 재주 | F12: 2 | G12: {=INDEX('규칙'!$C$26:$C$30,F12)} -> 9 | H12: {=INDEX('규칙'!$E$26:$E$30,F12)} -> 2 | K12: =(MAX(0,MIN(18,20-MAX(2,G12-2)))+1)/20 -> 0.7
A13: 늪지 | B13: 숨겨진 보물 | C13: 늪 속 살펴보기 | E13: 감지 | F13: 4 | G13: {=INDEX('규칙'!$C$26:$C$30,F13)} -> 15 | H13: {=INDEX('규칙'!$E$26:$E$30,F13)} -> 4 | J13: 18 | K13: =(MAX(0,MIN(18,20-MAX(2,G13-2)))+1)/20 -> 0.4
A14: 항구 마을 | B14: 숨겨진 보물 | C14: 부두 창고 살펴보기 | E14: 감지 | F14: 3 | G14: {=INDEX('규칙'!$C$26:$C$30,F14)} -> 12 | H14: {=INDEX('규칙'!$E$26:$E$30,F14)} -> 3 | J14: 18 | K14: =(MAX(0,MIN(18,20-MAX(2,G14-2)))+1)/20 -> 0.55
A15: 해변 | B15: 채집 | C15: 낚시하기 | D15: 회어 70% / 금린어 30% | E15: 재주 | F15: 2 | G15: {=INDEX('규칙'!$C$26:$C$30,F15)} -> 9 | H15: {=INDEX('규칙'!$E$26:$E$30,F15)} -> 2 | I15: 낚싯대 | K15: =(MAX(0,MIN(18,20-MAX(2,G15-2)))+1)/20 -> 0.7
A16: 협곡 | B16: 채집 | C16: 열매 따기 | D16: 산딸기 65% / 나무 열매 35% | E16: 재주 | F16: 1 | G16: {=INDEX('규칙'!$C$26:$C$30,F16)} -> 6 | H16: {=INDEX('규칙'!$E$26:$E$30,F16)} -> 1 | K16: =(MAX(0,MIN(18,20-MAX(2,G16-2)))+1)/20 -> 0.85
A17: 협곡 | B17: 채집 | C17: 광석 캐기 | D17: 철광석 75% / 유물 조각 25% | E17: 근력 | F17: 2 | G17: {=INDEX('규칙'!$C$26:$C$30,F17)} -> 9 | H17: {=INDEX('규칙'!$E$26:$E$30,F17)} -> 2 | I17: 곡괭이 | K17: =(MAX(0,MIN(18,20-MAX(2,G17-2)))+1)/20 -> 0.7
A18: 협곡 | B18: 숨겨진 보물 | C18: 절벽 틈 살펴보기 | E18: 감지 | F18: 4 | G18: {=INDEX('규칙'!$C$26:$C$30,F18)} -> 15 | H18: {=INDEX('규칙'!$E$26:$E$30,F18)} -> 4 | J18: 22 | K18: =(MAX(0,MIN(18,20-MAX(2,G18-2)))+1)/20 -> 0.4
A19: 설원 | B19: 채집 | C19: 약초 채집 | D19: 약초 65% / 독초 35% | E19: 재주 | F19: 3 | G19: {=INDEX('규칙'!$C$26:$C$30,F19)} -> 12 | H19: {=INDEX('규칙'!$E$26:$E$30,F19)} -> 3 | K19: =(MAX(0,MIN(18,20-MAX(2,G19-2)))+1)/20 -> 0.55
A20: 눈 마을 | B20: 숨겨진 보물 | C20: 눈 덮인 헛간 살펴보기 | E20: 감지 | F20: 4 | G20: {=INDEX('규칙'!$C$26:$C$30,F20)} -> 15 | H20: {=INDEX('규칙'!$E$26:$E$30,F20)} -> 4 | J20: 25 | K20: =(MAX(0,MIN(18,20-MAX(2,G20-2)))+1)/20 -> 0.4
A21: 동굴(북) | B21: 채집 | C21: 광석 캐기 | D21: 철광석 75% / 유물 조각 25% | E21: 근력 | F21: 3 | G21: {=INDEX('규칙'!$C$26:$C$30,F21)} -> 12 | H21: {=INDEX('규칙'!$E$26:$E$30,F21)} -> 3 | I21: 곡괭이 | K21: =(MAX(0,MIN(18,20-MAX(2,G21-2)))+1)/20 -> 0.55
A22: 동굴(북) | B22: 채집 | C22: 낚시하기 | D22: 회어 70% / 금린어 30% | E22: 재주 | F22: 2 | G22: {=INDEX('규칙'!$C$26:$C$30,F22)} -> 9 | H22: {=INDEX('규칙'!$E$26:$E$30,F22)} -> 2 | I22: 낚싯대 | K22: =(MAX(0,MIN(18,20-MAX(2,G22-2)))+1)/20 -> 0.7
A23: 동굴(북) | B23: 숨겨진 보물 | C23: 동굴 안쪽 살펴보기 | E23: 감지 | F23: 4 | G23: {=INDEX('규칙'!$C$26:$C$30,F23)} -> 15 | H23: {=INDEX('규칙'!$E$26:$E$30,F23)} -> 4 | J23: 20 | K23: =(MAX(0,MIN(18,20-MAX(2,G23-2)))+1)/20 -> 0.4
A24: 동굴(남) | B24: 채집 | C24: 광석 캐기 | D24: 철광석 75% / 유물 조각 25% | E24: 근력 | F24: 3 | G24: {=INDEX('규칙'!$C$26:$C$30,F24)} -> 12 | H24: {=INDEX('규칙'!$E$26:$E$30,F24)} -> 3 | I24: 곡괭이 | K24: =(MAX(0,MIN(18,20-MAX(2,G24-2)))+1)/20 -> 0.55
A25: 고대 유적 | B25: 채집 | C25: 광석 캐기 | D25: 철광석 50% / 유물 조각 50% | E25: 근력 | F25: 4 | G25: {=INDEX('규칙'!$C$26:$C$30,F25)} -> 15 | H25: {=INDEX('규칙'!$E$26:$E$30,F25)} -> 4 | I25: 곡괭이 | K25: =(MAX(0,MIN(18,20-MAX(2,G25-2)))+1)/20 -> 0.4
A26: 고대 유적 | B26: 숨겨진 보물 | C26: 제단 뒤 살펴보기 | E26: 감지 | F26: 5 | G26: {=INDEX('규칙'!$C$26:$C$30,F26)} -> 18 | H26: {=INDEX('규칙'!$E$26:$E$30,F26)} -> 5 | J26: 30 | K26: =(MAX(0,MIN(18,20-MAX(2,G26-2)))+1)/20 -> 0.25
A27: 고대 유적 | B27: 숨겨진 길 | C27: 숨겨진 길 찾기 | D27: 고대 유적↔오아시스 길이 열림 | E27: 감지 | F27: 4 | G27: {=INDEX('규칙'!$C$26:$C$30,F27)} -> 15 | H27: {=INDEX('규칙'!$E$26:$E$30,F27)} -> 4 | K27: =(MAX(0,MIN(18,20-MAX(2,G27-2)))+1)/20 -> 0.4
A28: 사막 | B28: 채집 | C28: 사막 채집 | D28: 선인장 열매 65% / 회전초 35% | E28: 재주 | F28: 2 | G28: {=INDEX('규칙'!$C$26:$C$30,F28)} -> 9 | H28: {=INDEX('규칙'!$E$26:$E$30,F28)} -> 2 | K28: =(MAX(0,MIN(18,20-MAX(2,G28-2)))+1)/20 -> 0.7
A29: 오아시스 | B29: 채집 | C29: 낚시하기 | D29: 회어 70% / 금린어 30% | E29: 재주 | F29: 2 | G29: {=INDEX('규칙'!$C$26:$C$30,F29)} -> 9 | H29: {=INDEX('규칙'!$E$26:$E$30,F29)} -> 2 | I29: 낚싯대 | K29: =(MAX(0,MIN(18,20-MAX(2,G29-2)))+1)/20 -> 0.7
A30: 오아시스 | B30: 채집 | C30: 사막 채집 | D30: 선인장 열매 65% / 회전초 35% | E30: 재주 | F30: 2 | G30: {=INDEX('규칙'!$C$26:$C$30,F30)} -> 9 | H30: {=INDEX('규칙'!$E$26:$E$30,F30)} -> 2 | K30: =(MAX(0,MIN(18,20-MAX(2,G30-2)))+1)/20 -> 0.7
A31: 오아시스 | B31: 숨겨진 보물 | C31: 물가 살펴보기 | E31: 감지 | F31: 3 | G31: {=INDEX('규칙'!$C$26:$C$30,F31)} -> 12 | H31: {=INDEX('규칙'!$E$26:$E$30,F31)} -> 3 | J31: 25 | K31: =(MAX(0,MIN(18,20-MAX(2,G31-2)))+1)/20 -> 0.55
A33: 채집은 성공하면 표의 확률대로 재료 하나를 얻음(크리티컬이면 뒤쪽의 귀한 재료 확정). 목표보다 6 이상 높거나 크리티컬이면 2개. 숨겨진 보물은 한 번 찾으면 사라짐.
A34: 같은 장소 도전을 60초 안에 3번 하면 10초 쿨타임.
A35: 채집 종류: 낚시(회어·금린어), 채집A(약초·독초), 채집B(산딸기·나무 열매), 버섯 따기(버섯·독버섯), 사막 채집(선인장 열매·회전초), 광석(철광석·유물 조각).

Sheet 장비
A1: 장비 | B1: 칸 | C1: 무기 분류 | D1: 공격 스탯 | E1: 단계 | F1: 근력 | G1: 정신 | H1: 민첩 | I1: 재주 | J1: 지력 | K1: 감지 | L1: 행운 | M1: 스탯 합계 | N1: 얻는 곳 | O1: 제작 재료 | P1: 제작 금화
A2: 나무 몽둥이 | B2: 무기 | C2: 근거리 | D2: 근력 | E2: 1 | F2: 3 | M2: =SUM(F2:L2) -> 3 | N2: 상점 | O2: -
A3: 경석궁 | B3: 무기 | C3: 원거리 | D3: 민첩 | E3: 1 | H3: 3 | M3: =SUM(F3:L3) -> 3 | N3: 상점 | O3: -
A4: 나무 지팡이 | B4: 무기 | C4: 마법 도구 | D4: 지력 | E4: 1 | J4: 3 | M4: =SUM(F4:L4) -> 3 | N4: 상점 | O4: -
A5: 사냥개 | B5: 무기 | C5: 사역마 | D5: 정신 | E5: 1 | G5: 3 | M5: =SUM(F5:L5) -> 3 | N5: 상점 | O5: -
A6: 철검 | B6: 무기 | C6: 근거리 | D6: 근력 | E6: 2 | F6: 4 | G6: 2 | M6: =SUM(F6:L6) -> 6 | N6: 의뢰 보상 / 제작 | O6: 철광석 2 | P6: 3
A7: 사냥꾼의 활 | B7: 무기 | C7: 원거리 | D7: 민첩 | E7: 2 | H7: 4 | K7: 2 | M7: =SUM(F7:L7) -> 6 | N7: 의뢰 보상 / 제작 | O7: 산딸기 3, 철광석 1 | P7: 3
A8: 수정 지팡이 | B8: 무기 | C8: 마법 도구 | D8: 지력 | E8: 2 | J8: 4 | L8: 2 | M8: =SUM(F8:L8) -> 6 | N8: 의뢰 보상 / 제작 | O8: 독초 2 | P8: 4
A9: 훈련된 매 | B9: 무기 | C9: 사역마 | D9: 정신 | E9: 2 | G9: 4 | K9: 2 | M9: =SUM(F9:L9) -> 6 | N9: 의뢰 보상 / 제작 | O9: 회어 3 | P9: 3
A10: 강철검 | B10: 무기 | C10: 근거리 | D10: 근력 | E10: 3 | F10: 6 | G10: 3 | H10: -2 | M10: =SUM(F10:L10) -> 7 | N10: 제작 | O10: 철광석 5, 약초 2 | P10: 10
A11: 강철 장궁 | B11: 무기 | C11: 원거리 | D11: 민첩 | E11: 3 | H11: 6 | K11: 3 | M11: =SUM(F11:L11) -> 9 | N11: 제작 | O11: 철광석 3, 회전초 2 | P11: 10
A12: 룬 지팡이 | B12: 무기 | C12: 마법 도구 | D12: 지력 | E12: 3 | J12: 6 | L12: 3 | M12: =SUM(F12:L12) -> 9 | N12: 제작 | O12: 유물 조각 2, 독초 2 | P12: 10
A13: 태엽 부엉이 | B13: 무기 | C13: 사역마 | D13: 정신 | E13: 3 | G13: 6 | K13: 3 | M13: =SUM(F13:L13) -> 9 | N13: 제작 | O13: 철광석 4, 금린어 2 | P13: 10
A14: 약초 망토 | B14: 방어구 | C14: - | D14: - | E14: - | G14: 2 | H14: 2 | M14: =SUM(F14:L14) -> 4 | N14: 제작 | O14: 약초 3, 버섯 3
A15: 철 갑옷 | B15: 방어구 | C15: - | D15: - | E15: - | G15: 6 | H15: -2 | M15: =SUM(F15:L15) -> 4 | N15: 제작 | O15: 철광석 6, 회어 3 | P15: 10
A17: 장비는 스탯을 올림(음수는 내림). 판정 보정은 장비 포함 스탯 ÷ 3이라 +3마다 판정 +1.
A18: 무기 분류별 공격 스탯: 근거리 근력 / 원거리 민첩 / 마법 도구 지력 / 사역마 정신. 무기가 없으면 맨손(근거리).
A19: 2단계 무기는 항구 상인의 몬스터 퇴치 의뢰 보상으로, 지금 쓰는 무기 분류에 맞춰 지급됨. 가방의 장비 칩을 누르면 바로 착용.

Sheet 상점
A1: 구매
A2: 물건 | B2: 시작 마을 (케르트) | C2: 항구 마을 (포체) | D2: 눈 마을 (헬라) | E2: 효과
A3: 나무 몽둥이 | B3: 4 | E3: 근거리 무기 · 근력 +3
A4: 경석궁 | B4: 5 | E4: 원거리 무기 · 민첩 +3
A5: 나무 지팡이 | B5: 5 | E5: 마법 도구 무기 · 지력 +3
A6: 사냥개 | B6: 5 | E6: 사역마 무기 · 정신 +3
A7: 낚싯대 | B7: 6 | C7: 5 | E7: 호수, 해변, 동굴, 오아시스에서 낚시할 때 필요
A8: 곡괭이 | B8: 8 | C8: 12 | D8: 7 | E8: 철광석과 유물 조각을 캘 때 필요
A9: 행운의 부적 | B9: 10 | C9: 14 | D9: 9 | E9: 모든 판정에 +1
A10: 마법 주사위 | C10: 45 | D10: 40 | E10: 주사위를 하나 더 굴려 높은 눈을 씀
A11: 수정 주사위 | D11: 130 | E11: 주사위를 하나 더 굴려 높은 눈을 씀
A15: 판매
A16: 재료 | B16: 기본 가격 | C16: 시작 마을 배율 | D16: 항구 마을 배율 | E16: 눈 마을 배율 | F16: 시작 마을 판매가 | G16: 항구 마을 판매가 | H16: 눈 마을 판매가
A17: 회어 | B17: 3 | C17: 1 | D17: 1.5 | E17: 0.7 | F17: =MAX(1,ROUND($B17*C17*(1+0.1*($B$31-2)),0)) -> 3 | G17: =MAX(1,ROUND($B17*D17*(1+0.1*($B$31-2)),0)) -> 5 | H17: =MAX(1,ROUND($B17*E17*(1+0.1*($B$31-2)),0)) -> 2
A18: 금린어 | B18: 8 | C18: 1 | D18: 1.5 | E18: 0.8 | F18: =MAX(1,ROUND($B18*C18*(1+0.1*($B$31-2)),0)) -> 8 | G18: =MAX(1,ROUND($B18*D18*(1+0.1*($B$31-2)),0)) -> 12 | H18: =MAX(1,ROUND($B18*E18*(1+0.1*($B$31-2)),0)) -> 6
A19: 약초 | B19: 4 | C19: 1 | D19: 0.9 | E19: 1.2 | F19: =MAX(1,ROUND($B19*C19*(1+0.1*($B$31-2)),0)) -> 4 | G19: =MAX(1,ROUND($B19*D19*(1+0.1*($B$31-2)),0)) -> 4 | H19: =MAX(1,ROUND($B19*E19*(1+0.1*($B$31-2)),0)) -> 5
A20: 독초 | B20: 5 | C20: 1 | D20: 1 | E20: 1.3 | F20: =MAX(1,ROUND($B20*C20*(1+0.1*($B$31-2)),0)) -> 5 | G20: =MAX(1,ROUND($B20*D20*(1+0.1*($B$31-2)),0)) -> 5 | H20: =MAX(1,ROUND($B20*E20*(1+0.1*($B$31-2)),0)) -> 7
A21: 산딸기 | B21: 2 | C21: 1 | D21: 1 | E21: 1 | F21: =MAX(1,ROUND($B21*C21*(1+0.1*($B$31-2)),0)) -> 2 | G21: =MAX(1,ROUND($B21*D21*(1+0.1*($B$31-2)),0)) -> 2 | H21: =MAX(1,ROUND($B21*E21*(1+0.1*($B$31-2)),0)) -> 2
A22: 나무 열매 | B22: 3 | C22: 1 | D22: 1 | E22: 1 | F22: =MAX(1,ROUND($B22*C22*(1+0.1*($B$31-2)),0)) -> 3 | G22: =MAX(1,ROUND($B22*D22*(1+0.1*($B$31-2)),0)) -> 3 | H22: =MAX(1,ROUND($B22*E22*(1+0.1*($B$31-2)),0)) -> 3
A23: 버섯 | B23: 2 | C23: 1 | D23: 1 | E23: 1 | F23: =MAX(1,ROUND($B23*C23*(1+0.1*($B$31-2)),0)) -> 2 | G23: =MAX(1,ROUND($B23*D23*(1+0.1*($B$31-2)),0)) -> 2 | H23: =MAX(1,ROUND($B23*E23*(1+0.1*($B$31-2)),0)) -> 2
A24: 독버섯 | B24: 4 | C24: 1 | D24: 1 | E24: 1 | F24: =MAX(1,ROUND($B24*C24*(1+0.1*($B$31-2)),0)) -> 4 | G24: =MAX(1,ROUND($B24*D24*(1+0.1*($B$31-2)),0)) -> 4 | H24: =MAX(1,ROUND($B24*E24*(1+0.1*($B$31-2)),0)) -> 4
A25: 선인장 열매 | B25: 4 | C25: 1 | D25: 1 | E25: 1 | F25: =MAX(1,ROUND($B25*C25*(1+0.1*($B$31-2)),0)) -> 4 | G25: =MAX(1,ROUND($B25*D25*(1+0.1*($B$31-2)),0)) -> 4 | H25: =MAX(1,ROUND($B25*E25*(1+0.1*($B$31-2)),0)) -> 4
A26: 회전초 | B26: 3 | C26: 1 | D26: 1 | E26: 1 | F26: =MAX(1,ROUND($B26*C26*(1+0.1*($B$31-2)),0)) -> 3 | G26: =MAX(1,ROUND($B26*D26*(1+0.1*($B$31-2)),0)) -> 3 | H26: =MAX(1,ROUND($B26*E26*(1+0.1*($B$31-2)),0)) -> 3
A27: 철광석 | B27: 6 | C27: 1 | D27: 0.8 | E27: 1.3 | F27: =MAX(1,ROUND($B27*C27*(1+0.1*($B$31-2)),0)) -> 6 | G27: =MAX(1,ROUND($B27*D27*(1+0.1*($B$31-2)),0)) -> 5 | H27: =MAX(1,ROUND($B27*E27*(1+0.1*($B$31-2)),0)) -> 8
A28: 유물 조각 | B28: 10 | C28: 1 | D28: 1 | E28: 1.2 | F28: =MAX(1,ROUND($B28*C28*(1+0.1*($B$31-2)),0)) -> 10 | G28: =MAX(1,ROUND($B28*D28*(1+0.1*($B$31-2)),0)) -> 10 | H28: =MAX(1,ROUND($B28*E28*(1+0.1*($B$31-2)),0)) -> 12
A31: 지력 판정 보정 | B31: 2 | C31: 판매가 = 기본 가격 × 마을 배율 × (1 + 0.1 × (지력 판정 보정 - 2)), 반올림. 지력 6~8(보정 +2)이 기준.
